Workbook

Sheet Outreach
A1: Company | R1: Contact — fill in | W1: Nearest pitch | Z1: Lead with (message) | AM1: Tracking — fill in
A2: # | B2: Priority | C2: Segment | D2: Area | E2: Company | F2: Name for messages | G2: Website | H2: Email | I2: Email type | J2: Email source | K2: Companies House no. | L2: Companies House | M2: Accounts | N2: Incorporated | O2: Registered address | P2: Postcode | Q2: In 933 research list? | R2: Contact first name | S2: Contact full name | T2: Job title | U2: Direct email | V2: Phone | W2: Nearest pitch | X2: Walk (min) | Y2: Other pitches ≤19 min | Z2: Lead with: pitch | AA2: Walk to it (min) | AB2: Pitch status | AC2: Open slots | AD2: Lead with: slot | AE2: Lead with: format | AF2: Price per player (£) | AG2: Lead-with line | AH2: Send to | AI2: Subject | AJ2: Email draft | AK2: Follow-up email (day 4) | AL2: Draft status | AM2: Owner | AN2: Channel | AO2: Contacted on | AP2: Follow-up sent on | AQ2: Replied | AR2: Call booked | AS2: Group created | AT2: First game booked | AU2: Second game booked | AV2: Objection (exact words) | AW2: Next step | AX2: Notes
A3: 1 | B3: 1 | C3: Law firm | D3: City of London | E3: Allen Overy Shearman Sterling LLP | F3: A&O Shearman | G3: https://www.aoshearman.com | H3: dparisi@aoshearman.com | I3: named person | J3: Open page | K3: OC306763 | L3: Open | M3: Group | N3: 38016 | O3: One Bishops Square, London | P3: E1 6AD | Q3: No | W3: Liverpool St - Attlee Centre | X3: 6 | Y3: Shoreditch Powerleague (6.5) | Z3: Shoreditch Powerleague | AA3: 6 | AB3: =IFERROR(INDEX(Venues!$E$2:$E$17,MATCH(Z3,Venues!$A$2:$A$17,0)),"Not checked") | AC3: =IFERROR(INDEX(Venues!$F$2:$F$17,MATCH(Z3,Venues!$A$2:$A$17,0)),0) | AD3: =IFERROR(INDEX(Venues!$M$2:$M$17,MATCH(Z3,Venues!$A$2:$A$17,0)),"") | AE3: =IFERROR(INDEX(Venues!$N$2:$N$17,MATCH(Z3,Venues!$A$2:$A$17,0)),"5-a-side") | AF3: =IF(Offer!$C$4="","",Offer!$C$4) | AG3: =Z3&" ("&AA3&" min walk) · "&IF(ISNUMBER(AD3),TEXT(AD3,"ddd d mmm, hh:mm"),"slot to confirm with venue")&" · "&AE3&" · "&IF(AF3<>"","£"&TEXT(AF3,"0.00")&" pp","price TBC") | AH3: =IF(U3<>"",U3,IF(H3<>"",H3,"")) | AI3: ="After-work football for "&F3&" · "&Z3&", "&AA3&" min from your office" | AJ3: ="Hi "&IF(R3<>"",R3,F3&" team")&","&CHAR(10)&CHAR(10)&"I'm "&IF(AM3<>"",AM3,IF(Offer!$C$5<>"",Offer!$C$5,"[NAME]"))&" from FC Urban. We organise after-work football for teams in the City and Canary Wharf."&CHAR(10)&CHAR(10)&"We have a "&AE3&" pitch at "&Z3&", "&IF(OR(AA3=8,AA3=11,AA3=18),"an ","a ")&AA3&"-minute walk from your "&P3&" office, "&IF(ISNUMBER(AD3),"on "&TEXT(AD3,"dddd d mmmm")&" at "&TEXT(AD3,"hh:mm"),"on a weekday evening that suits your team")&". It's "&IF(AF3<>"","£"&IF(AF3=INT(AF3),TEXT(AF3,"0"),TEXT(AF3,"0.00")),"[PRICE PER PLAYER]")&" a player and we handle the pitch booking, sign-ups and payments, so all it takes is one person sharing a link with the team."&CHAR(10)&CHAR(10)&"It works well as a team social or "&IF(ISNUMBER(SEARCH(LEFT(F3,1),"AEIOU")),"an ","a ")&F3&" vs clients game. Would your team be up for it, or is there someone who'd enjoy organising it?"&IF(Offer!$C$7<>""," Spots are held until "&TEXT(Offer!$C$7,"dddd d mmmm")&".","")&" "&IF(Offer!$C$6<>"",Offer!$C$6,"[JOINING LINK]")&CHAR(10)&CHAR(10)&"Best,"&CHAR(10)&IF(AM3<>"",AM3,IF(Offer!$C$5<>"",Offer!$C$5,"[NAME]"))&CHAR(10)&"FC Urban" | AK3: ="Hi "&IF(R3<>"",R3,F3&" team")&","&CHAR(10)&CHAR(10)&"Just bumping this up. The "&AE3&" pitch at "&Z3&" is still free "&IF(ISNUMBER(AD3),TEXT(AD3,"ddd d mmm")&", "&TEXT(AD3,"hh:mm"),"weekday evenings")&", "&IF(OR(AA3=8,AA3=11,AA3=18),"an ","a ")&AA3&"-minute walk from your office, "&IF(AF3<>"","£"&IF(AF3=INT(AF3),TEXT(AF3,"0"),TEXT(AF3,"0.00")),"[PRICE PER PLAYER]")&" a player. Happy to hold it for "&F3&" if someone on the team fancies organising a game."&IF(Offer!$C$7<>""," Spots are held until "&TEXT(Offer!$C$7,"dddd d mmmm")&".","")&" "&IF(Offer!$C$6<>"",Offer!$C$6,"[JOINING LINK]")&CHAR(10)&CHAR(10)&"Best,"&CHAR(10)&IF(AM3<>"",AM3,IF(Offer!$C$5<>"",Offer!$C$5,"[NAME]"))&CHAR(10)&"FC Urban" | AL3: =IF(AH3="","No email yet",IF(ISNUMBER(SEARCH("[",AJ3)),"Fill placeholders",IF(ISNUMBER(AD3),"Ready to send","Ready · no fixed slot")))
A4: 2 | B4: 1 | C4: Law firm | D4: City of London | E4: Baker & McKenzie LLP | F4: Baker McKenzie | G4: https://www.bakermckenzie.com | H4: hkalumni@bakermckenzie.com | I4: named person | J4: Open page | K4: OC311297 | L4: Open | M4: Group | N4: 38384 | O4: 280 Bishopsgate, London | P4: EC2M 4AG | Q4: No | W4: Shoreditch Powerleague | X4: 7 | Y4: Liverpool St - Attlee Centre (7.1) | Z4: Shoreditch Powerleague | AA4: 7 | AB4: =IFERROR(INDEX(Venues!$E$2:$E$17,MATCH(Z4,Venues!$A$2:$A$17,0)),"Not checked") | AC4: =IFERROR(INDEX(Venues!$F$2:$F$17,MATCH(Z4,Venues!$A$2:$A$17,0)),0) | AD4: =IFERROR(INDEX(Venues!$M$2:$M$17,MATCH(Z4,Venues!$A$2:$A$17,0)),"") | AE4: =IFERROR(INDEX(Venues!$N$2:$N$17,MATCH(Z4,Venues!$A$2:$A$17,0)),"5-a-side") | AF4: =IF(Offer!$C$4="","",Offer!$C$4) | AG4: =Z4&" ("&AA4&" min walk) · "&IF(ISNUMBER(AD4),TEXT(AD4,"ddd d mmm, hh:mm"),"slot to confirm with venue")&" · "&AE4&" · "&IF(AF4<>"","£"&TEXT(AF4,"0.00")&" pp","price TBC") | AH4: =IF(U4<>"",U4,IF(H4<>"",H4,"")) | AI4: ="After-work football for "&F4&" · "&Z4&", "&AA4&" min from your office" | AJ4: ="Hi "&IF(R4<>"",R4,F4&" team")&","&CHAR(10)&CHAR(10)&"I'm "&IF(AM4<>"",AM4,IF(Offer!$C$5<>"",Offer!$C$5,"[NAME]"))&" from FC Urban. We organise after-work football for teams in the City and Canary Wharf."&CHAR(10)&CHAR(10)&"We have a "&AE4&" pitch at "&Z4&", "&IF(OR(AA4=8,AA4=11,AA4=18),"an ","a ")&AA4&"-minute walk from your "&P4&" office, "&IF(ISNUMBER(AD4),"on "&TEXT(AD4,"dddd d mmmm")&" at "&TEXT(AD4,"hh:mm"),"on a weekday evening that suits your team")&". It's "&IF(AF4<>"","£"&IF(AF4=INT(AF4),TEXT(AF4,"0"),TEXT(AF4,"0.00")),"[PRICE PER PLAYER]")&" a player and we handle the pitch booking, sign-ups and payments, so all it takes is one person sharing a link with the team."&CHAR(10)&CHAR(10)&"It works well as a team social or "&IF(ISNUMBER(SEARCH(LEFT(F4,1),"AEIOU")),"an ","a ")&F4&" vs clients game. Would your team be up for it, or is there someone who'd enjoy organising it?"&IF(Offer!$C$7<>""," Spots are held until "&TEXT(Offer!$C$7,"dddd d mmmm")&".","")&" "&IF(Offer!$C$6<>"",Offer!$C$6,"[JOINING LINK]")&CHAR(10)&CHAR(10)&"Best,"&CHAR(10)&IF(AM4<>"",AM4,IF(Offer!$C$5<>"",Offer!$C$5,"[NAME]"))&CHAR(10)&"FC Urban" | AK4: ="Hi "&IF(R4<>"",R4,F4&" team")&","&CHAR(10)&CHAR(10)&"Just bumping this up. The "&AE4&" pitch at "&Z4&" is still free "&IF(ISNUMBER(AD4),TEXT(AD4,"ddd d mmm")&", "&TEXT(AD4,"hh:mm"),"weekday evenings")&", "&IF(OR(AA4=8,AA4=11,AA4=18),"an ","a ")&AA4&"-minute walk from your office, "&IF(AF4<>"","£"&IF(AF4=INT(AF4),TEXT(AF4,"0"),TEXT(AF4,"0.00")),"[PRICE PER PLAYER]")&" a player. Happy to hold it for "&F4&" if someone on the team fancies organising a game."&IF(Offer!$C$7<>""," Spots are held until "&TEXT(Offer!$C$7,"dddd d mmmm")&".","")&" "&IF(Offer!$C$6<>"",Offer!$C$6,"[JOINING LINK]")&CHAR(10)&CHAR(10)&"Best,"&CHAR(10)&IF(AM4<>"",AM4,IF(Offer!$C$5<>"",Offer!$C$5,"[NAME]"))&CHAR(10)&"FC Urban" | AL4: =IF(AH4="","No email yet",IF(ISNUMBER(SEARCH("[",AJ4)),"Fill placeholders",IF(ISNUMBER(AD4),"Ready to send","Ready · no fixed slot")))
A5: 3 | B5: 1 | C5: Law firm | D5: City of London | E5: Shoosmiths LLP | F5: Shoosmiths | G5: https://www.shoosmiths.com | H5: generalenquiries@shoosmiths.com | I5: named person | J5: Open page | K5: OC374987 | L5: Open | M5: Group | N5: 41033 | O5: 1 Bow Churchyard, London | P5: EC4M 9DQ | Q5: No | W5: City of London School (EC4V 3AL) | X5: 8 | Y5: Marlborough Sports Garden (SE1 1SD) (18.1) | Z5: City of London School (EC4V 3AL) | AA5: 8 | AB5: =IFERROR(INDEX(Venues!$E$2:$E$17,MATCH(Z5,Venues!$A$2:$A$17,0)),"Not checked") | AC5: =IFERROR(INDEX(Venues!$F$2:$F$17,MATCH(Z5,Venues!$A$2:$A$17,0)),0) | AD5: =IFERROR(INDEX(Venues!$M$2:$M$17,MATCH(Z5,Venues!$A$2:$A$17,0)),"") | AE5: =IFERROR(INDEX(Venues!$N$2:$N$17,MATCH(Z5,Venues!$A$2:$A$17,0)),"5-a-side") | AF5: =IF(Offer!$C$4="","",Offer!$C$4) | AG5: =Z5&" ("&AA5&" min walk) · "&IF(ISNUMBER(AD5),TEXT(AD5,"ddd d mmm, hh:mm"),"slot to confirm with venue")&" · "&AE5&" · "&IF(AF5<>"","£"&TEXT(AF5,"0.00")&" pp","price TBC") | AH5: =IF(U5<>"",U5,IF(H5<>"",H5,"")) | AI5: ="After-work football for "&F5&" · "&Z5&", "&AA5&" min from your office" | AJ5: ="Hi "&IF(R5<>"",R5,F5&" team")&","&CHAR(10)&CHAR(10)&"I'm "&IF(AM5<>"",AM5,IF(Offer!$C$5<>"",Offer!$C$5,"[NAME]"))&" from FC Urban. We organise after-work football for teams in the City and Canary Wharf."&CHAR(10)&CHAR(10)&"We have a "&AE5&" pitch at "&Z5&", "&IF(OR(AA5=8,AA5=11,AA5=18),"an ","a ")&AA5&"-minute walk from your "&P5&" office, "&IF(ISNUMBER(AD5),"on "&TEXT(AD5,"dddd d mmmm")&" at "&TEXT(AD5,"hh:mm"),"on a weekday evening that suits your team")&". It's "&IF(AF5<>"","£"&IF(AF5=INT(AF5),TEXT(AF5,"0"),TEXT(AF5,"0.00")),"[PRICE PER PLAYER]")&" a player and we handle the pitch booking, sign-ups and payments, so all it takes is one person sharing a link with the team."&CHAR(10)&CHAR(10)&"It works well as a team social or "&IF(ISNUMBER(SEARCH(LEFT(F5,1),"AEIOU")),"an ","a ")&F5&" vs clients game. Would your team be up for it, or is there someone who'd enjoy organising it?"&IF(Offer!$C$7<>""," Spots are held until "&TEXT(Offer!$C$7,"dddd d mmmm")&".","")&" "&IF(Offer!$C$6<>"",Offer!$C$6,"[JOINING LINK]")&CHAR(10)&CHAR(10)&"Best,"&CHAR(10)&IF(AM5<>"",AM5,IF(Offer!$C$5<>"",Offer!$C$5,"[NAME]"))&CHAR(10)&"FC Urban" | AK5: ="Hi "&IF(R5<>"",R5,F5&" team")&","&CHAR(10)&CHAR(10)&"Just bumping this up. The "&AE5&" pitch at "&Z5&" is still free "&IF(ISNUMBER(AD5),TEXT(AD5,"ddd d mmm")&", "&TEXT(AD5,"hh:mm"),"weekday evenings")&", "&IF(OR(AA5=8,AA5=11,AA5=18),"an ","a ")&AA5&"-minute walk from your office, "&IF(AF5<>"","£"&IF(AF5=INT(AF5),TEXT(AF5,"0"),TEXT(AF5,"0.00")),"[PRICE PER PLAYER]")&" a player. Happy to hold it for "&F5&" if someone on the team fancies organising a game."&IF(Offer!$C$7<>""," Spots are held until "&TEXT(Offer!$C$7,"dddd d mmmm")&".","")&" "&IF(Offer!$C$6<>"",Offer!$C$6,"[JOINING LINK]")&CHAR(10)&CHAR(10)&"Best,"&CHAR(10)&IF(AM5<>"",AM5,IF(Offer!$C$5<>"",Offer!$C$5,"[NAME]"))&CHAR(10)&"FC Urban" | AL5: =IF(AH5="","No email yet",IF(ISNUMBER(SEARCH("[",AJ5)),"Fill placeholders",IF(ISNUMBER(AD5),"Ready to send","Ready · no fixed slot")))
A6: 4 | B6: 1 | C6: Law firm | D6: City of London | E6: Herbert Smith Freehills Kramer Global LLP | F6: Herbert Smith Freehills Kramer | G6: https://www.hsfkramer.com | I6: Not found | K6: OC375784 | L6: Open | M6: Group | N6: 41066 | O6: Exchange House, Primrose Street, London | P6: EC2A 2EG | Q6: No | W6: Shoreditch Powerleague | X6: 8 | Y6: Liverpool St - Attlee Centre (9.8) | Z6: Shoreditch Powerleague | AA6: 8 | AB6: =IFERROR(INDEX(Venues!$E$2:$E$17,MATCH(Z6,Venues!$A$2:$A$17,0)),"Not checked") | AC6: =IFERROR(INDEX(Venues!$F$2:$F$17,MATCH(Z6,Venues!$A$2:$A$17,0)),0) | AD6: =IFERROR(INDEX(Venues!$M$2:$M$17,MATCH(Z6,Venues!$A$2:$A$17,0)),"") | AE6: =IFERROR(INDEX(Venues!$N$2:$N$17,MATCH(Z6,Venues!$A$2:$A$17,0)),"5-a-side") | AF6: =IF(Offer!$C$4="","",Offer!$C$4) | AG6: =Z6&" ("&AA6&" min walk) · "&IF(ISNUMBER(AD6),TEXT(AD6,"ddd d mmm, hh:mm"),"slot to confirm with venue")&" · "&AE6&" · "&IF(AF6<>"","£"&TEXT(AF6,"0.00")&" pp","price TBC") | AH6: =IF(U6<>"",U6,IF(H6<>"",H6,"")) | AI6: ="After-work football for "&F6&" · "&Z6&", "&AA6&" min from your office" | AJ6: ="Hi "&IF(R6<>"",R6,F6&" team")&","&CHAR(10)&CHAR(10)&"I'm "&IF(AM6<>"",AM6,IF(Offer!$C$5<>"",Offer!$C$5,"[NAME]"))&" from FC Urban. We organise after-work football for teams in the City and Canary Wharf."&CHAR(10)&CHAR(10)&"We have a "&AE6&" pitch at "&Z6&", "&IF(OR(AA6=8,AA6=11,AA6=18),"an ","a ")&AA6&"-minute walk from your "&P6&" office, "&IF(ISNUMBER(AD6),"on "&TEXT(AD6,"dddd d mmmm")&" at "&TEXT(AD6,"hh:mm"),"on a weekday evening that suits your team")&". It's "&IF(AF6<>"","£"&IF(AF6=INT(AF6),TEXT(AF6,"0"),TEXT(AF6,"0.00")),"[PRICE PER PLAYER]")&" a player and we handle the pitch booking, sign-ups and payments, so all it takes is one person sharing a link with the team."&CHAR(10)&CHAR(10)&"It works well as a team social or "&IF(ISNUMBER(SEARCH(LEFT(F6,1),"AEIOU")),"an ","a ")&F6&" vs clients game. Would your team be up for it, or is there someone who'd enjoy organising it?"&IF(Offer!$C$7<>""," Spots are held until "&TEXT(Offer!$C$7,"dddd d mmmm")&".","")&" "&IF(Offer!$C$6<>"",Offer!$C$6,"[JOINING LINK]")&CHAR(10)&CHAR(10)&"Best,"&CHAR(10)&IF(AM6<>"",AM6,IF(Offer!$C$5<>"",Offer!$C$5,"[NAME]"))&CHAR(10)&"FC Urban" | AK6: ="Hi "&IF(R6<>"",R6,F6&" team")&","&CHAR(10)&CHAR(10)&"Just bumping this up. The "&AE6&" pitch at "&Z6&" is still free "&IF(ISNUMBER(AD6),TEXT(AD6,"ddd d mmm")&", "&TEXT(AD6,"hh:mm"),"weekday evenings")&", "&IF(OR(AA6=8,AA6=11,AA6=18),"an ","a ")&AA6&"-minute walk from your office, "&IF(AF6<>"","£"&IF(AF6=INT(AF6),TEXT(AF6,"0"),TEXT(AF6,"0.00")),"[PRICE PER PLAYER]")&" a player. Happy to hold it for "&F6&" if someone on the team fancies organising a game."&IF(Offer!$C$7<>""," Spots are held until "&TEXT(Offer!$C$7,"dddd d mmmm")&".","")&" "&IF(Offer!$C$6<>"",Offer!$C$6,"[JOINING LINK]")&CHAR(10)&CHAR(10)&"Best,"&CHAR(10)&IF(AM6<>"",AM6,IF(Offer!$C$5<>"",Offer!$C$5,"[NAME]"))&CHAR(10)&"FC Urban" | AL6: =IF(AH6="","No email yet",IF(ISNUMBER(SEARCH("[",AJ6)),"Fill placeholders",IF(ISNUMBER(AD6),"Ready to send","Ready · no fixed slot")))
A7: 5 | B7: 1 | C7: Law firm | D7: City of London | E7: Ashurst Perkins Coie UK LLP | F7: Ashurst Perkins Coie | G7: https://www.ashurstperkinscoie.com | H7: london@ashurstperkinscoie.com | I7: general | J7: Open page | K7: OC330252 | L7: Open | M7: Group | N7: 39294 | O7: 1 Duval Square, London Fruit And Wool Exchange, London | P7: E1 6PW | Q7: No | W7: Liverpool St - Attlee Centre | X7: 3 | Y7: Shoreditch Powerleague (8.1); Whitechapel (18.6) | Z7: Shoreditch Powerleague | AA7: 8 | AB7: =IFERROR(INDEX(Venues!$E$2:$E$17,MATCH(Z7,Venues!$A$2:$A$17,0)),"Not checked") | AC7: =IFERROR(INDEX(Venues!$F$2:$F$17,MATCH(Z7,Venues!$A$2:$A$17,0)),0) | AD7: =IFERROR(INDEX(Venues!$M$2:$M$17,MATCH(Z7,Venues!$A$2:$A$17,0)),"") | AE7: =IFERROR(INDEX(Venues!$N$2:$N$17,MATCH(Z7,Venues!$A$2:$A$17,0)),"5-a-side") | AF7: =IF(Offer!$C$4="","",Offer!$C$4) | AG7: =Z7&" ("&AA7&" min walk) · "&IF(ISNUMBER(AD7),TEXT(AD7,"ddd d mmm, hh:mm"),"slot to confirm with venue")&" · "&AE7&" · "&IF(AF7<>"","£"&TEXT(AF7,"0.00")&" pp","price TBC") | AH7: =IF(U7<>"",U7,IF(H7<>"",H7,"")) | AI7: ="After-work football for "&F7&" · "&Z7&", "&AA7&" min from your office" | AJ7: ="Hi "&IF(R7<>"",R7,F7&" team")&","&CHAR(10)&CHAR(10)&"I'm "&IF(AM7<>"",AM7,IF(Offer!$C$5<>"",Offer!$C$5,"[NAME]"))&" from FC Urban. We organise after-work football for teams in the City and Canary Wharf."&CHAR(10)&CHAR(10)&"We have a "&AE7&" pitch at "&Z7&", "&IF(OR(AA7=8,AA7=11,AA7=18),"an ","a ")&AA7&"-minute walk from your "&P7&" office, "&IF(ISNUMBER(AD7),"on "&TEXT(AD7,"dddd d mmmm")&" at "&TEXT(AD7,"hh:mm"),"on a weekday evening that suits your team")&". It's "&IF(AF7<>"","£"&IF(AF7=INT(AF7),TEXT(AF7,"0"),TEXT(AF7,"0.00")),"[PRICE PER PLAYER]")&" a player and we handle the pitch booking, sign-ups and payments, so all it takes is one person sharing a link with the team."&CHAR(10)&CHAR(10)&"It works well as a team social or "&IF(ISNUMBER(SEARCH(LEFT(F7,1),"AEIOU")),"an ","a ")&F7&" vs clients game. Would your team be up for it, or is there someone who'd enjoy organising it?"&IF(Offer!$C$7<>""," Spots are held until "&TEXT(Offer!$C$7,"dddd d mmmm")&".","")&" "&IF(Offer!$C$6<>"",Offer!$C$6,"[JOINING LINK]")&CHAR(10)&CHAR(10)&"Best,"&CHAR(10)&IF(AM7<>"",AM7,IF(Offer!$C$5<>"",Offer!$C$5,"[NAME]"))&CHAR(10)&"FC Urban" | AK7: ="Hi "&IF(R7<>"",R7,F7&" team")&","&CHAR(10)&CHAR(10)&"Just bumping this up. The "&AE7&" pitch at "&Z7&" is still free "&IF(ISNUMBER(AD7),TEXT(AD7,"ddd d mmm")&", "&TEXT(AD7,"hh:mm"),"weekday evenings")&", "&IF(OR(AA7=8,AA7=11,AA7=18),"an ","a ")&AA7&"-minute walk from your office, "&IF(AF7<>"","£"&IF(AF7=INT(AF7),TEXT(AF7,"0"),TEXT(AF7,"0.00")),"[PRICE PER PLAYER]")&" a player. Happy to hold it for "&F7&" if someone on the team fancies organising a game."&IF(Offer!$C$7<>""," Spots are held until "&TEXT(Offer!$C$7,"dddd d mmmm")&".","")&" "&IF(Offer!$C$6<>"",Offer!$C$6,"[JOINING LINK]")&CHAR(10)&CHAR(10)&"Best,"&CHAR(10)&IF(AM7<>"",AM7,IF(Offer!$C$5<>"",Offer!$C$5,"[NAME]"))&CHAR(10)&"FC Urban" | AL7: =IF(AH7="","No email yet",IF(ISNUMBER(SEARCH("[",AJ7)),"Fill placeholders",IF(ISNUMBER(AD7),"Ready to send","Ready · no fixed slot")))
A8: 6 | B8: 1 | C8: Law firm | D8: City of London | E8: Carey Olsen LLP | F8: Carey Olsen | G8: https://www.careyolsen.com | H8: londonco@careyolsen.com | I8: general | J8: Open page | K8: OC345292 | L8: Open | M8: Group | N8: 39932 | O8: Forum St Pauls, 33 Gutter Lane, London | P8: EC2V 8AS | Q8: No | W8: City of London School (EC4V 3AL) | X8: 9 | Z8: City of London School (EC4V 3AL) | AA8: 9 | AB8: =IFERROR(INDEX(Venues!$E$2:$E$17,MATCH(Z8,Venues!$A$2:$A$17,0)),"Not checked") | AC8: =IFERROR(INDEX(Venues!$F$2:$F$17,MATCH(Z8,Venues!$A$2:$A$17,0)),0) | AD8: =IFERROR(INDEX(Venues!$M$2:$M$17,MATCH(Z8,Venues!$A$2:$A$17,0)),"") | AE8: =IFERROR(INDEX(Venues!$N$2:$N$17,MATCH(Z8,Venues!$A$2:$A$17,0)),"5-a-side") | AF8: =IF(Offer!$C$4="","",Offer!$C$4) | AG8: =Z8&" ("&AA8&" min walk) · "&IF(ISNUMBER(AD8),TEXT(AD8,"ddd d mmm, hh:mm"),"slot to confirm with venue")&" · "&AE8&" · "&IF(AF8<>"","£"&TEXT(AF8,"0.00")&" pp","price TBC") | AH8: =IF(U8<>"",U8,IF(H8<>"",H8,"")) | AI8: ="After-work football for "&F8&" · "&Z8&", "&AA8&" min from your office" | AJ8: ="Hi "&IF(R8<>"",R8,F8&" team")&","&CHAR(10)&CHAR(10)&"I'm "&IF(AM8<>"",AM8,IF(Offer!$C$5<>"",Offer!$C$5,"[NAME]"))&" from FC Urban. We organise after-work football for teams in the City and Canary Wharf."&CHAR(10)&CHAR(10)&"We have a "&AE8&" pitch at "&Z8&", "&IF(OR(AA8=8,AA8=11,AA8=18),"an ","a ")&AA8&"-minute walk from your "&P8&" office, "&IF(ISNUMBER(AD8),"on "&TEXT(AD8,"dddd d mmmm")&" at "&TEXT(AD8,"hh:mm"),"on a weekday evening that suits your team")&". It's "&IF(AF8<>"","£"&IF(AF8=INT(AF8),TEXT(AF8,"0"),TEXT(AF8,"0.00")),"[PRICE PER PLAYER]")&" a player and we handle the pitch booking, sign-ups and payments, so all it takes is one person sharing a link with the team."&CHAR(10)&CHAR(10)&"It works well as a team social or "&IF(ISNUMBER(SEARCH(LEFT(F8,1),"AEIOU")),"an ","a ")&F8&" vs clients game. Would your team be up for it, or is there someone who'd enjoy organising it?"&IF(Offer!$C$7<>""," Spots are held until "&TEXT(Offer!$C$7,"dddd d mmmm")&".","")&" "&IF(Offer!$C$6<>"",Offer!$C$6,"[JOINING LINK]")&CHAR(10)&CHAR(10)&"Best,"&CHAR(10)&IF(AM8<>"",AM8,IF(Offer!$C$5<>"",Offer!$C$5,"[NAME]"))&CHAR(10)&"FC Urban" | AK8: ="Hi "&IF(R8<>"",R8,F8&" team")&","&CHAR(10)&CHAR(10)&"Just bumping this up. The "&AE8&" pitch at "&Z8&" is still free "&IF(ISNUMBER(AD8),TEXT(AD8,"ddd d mmm")&", "&TEXT(AD8,"hh:mm"),"weekday evenings")&", "&IF(OR(AA8=8,AA8=11,AA8=18),"an ","a ")&AA8&"-minute walk from your office, "&IF(AF8<>"","£"&IF(AF8=INT(AF8),TEXT(AF8,"0"),TEXT(AF8,"0.00")),"[PRICE PER PLAYER]")&" a player. Happy to hold it for "&F8&" if someone on the team fancies organising a game."&IF(Offer!$C$7<>""," Spots are held until "&TEXT(Offer!$C$7,"dddd d mmmm")&".","")&" "&IF(Offer!$C$6<>"",Offer!$C$6,"[JOINING LINK]")&CHAR(10)&CHAR(10)&"Best,"&CHAR(10)&IF(AM8<>"",AM8,IF(Offer!$C$5<>"",Offer!$C$5,"[NAME]"))&CHAR(10)&"FC Urban" | AL8: =IF(AH8="","No email yet",IF(ISNUMBER(SEARCH("[",AJ8)),"Fill placeholders",IF(ISNUMBER(AD8),"Ready to send","Ready · no fixed slot")))
A9: 7 | B9: 1 | C9: Law firm | D9: City of London | E9: Eversheds Sutherland (International) LLP | F9: Eversheds Sutherland | G9: https://www.eversheds-sutherland.com | H9: rachelreid@eversheds-sutherland.com | I9: named person | J9: Open page | K9: OC304065 | L9: Open | M9: Group | N9: 37685 | O9: One Wood Street, London | P9: EC2V 7WS | Q9: No | W9: City of London School (EC4V 3AL) | X9: 9 | Z9: City of London School (EC4V 3AL) | AA9: 9 | AB9: =IFERROR(INDEX(Venues!$E$2:$E$17,MATCH(Z9,Venues!$A$2:$A$17,0)),"Not checked") | AC9: =IFERROR(INDEX(Venues!$F$2:$F$17,MATCH(Z9,Venues!$A$2:$A$17,0)),0) | AD9: =IFERROR(INDEX(Venues!$M$2:$M$17,MATCH(Z9,Venues!$A$2:$A$17,0)),"") | AE9: =IFERROR(INDEX(Venues!$N$2:$N$17,MATCH(Z9,Venues!$A$2:$A$17,0)),"5-a-side") | AF9: =IF(Offer!$C$4="","",Offer!$C$4) | AG9: =Z9&" ("&AA9&" min walk) · "&IF(ISNUMBER(AD9),TEXT(AD9,"ddd d mmm, hh:mm"),"slot to confirm with venue")&" · "&AE9&" · "&IF(AF9<>"","£"&TEXT(AF9,"0.00")&" pp","price TBC") | AH9: =IF(U9<>"",U9,IF(H9<>"",H9,"")) | AI9: ="After-work football for "&F9&" · "&Z9&", "&AA9&" min from your office" | AJ9: ="Hi "&IF(R9<>"",R9,F9&" team")&","&CHAR(10)&CHAR(10)&"I'm "&IF(AM9<>"",AM9,IF(Offer!$C$5<>"",Offer!$C$5,"[NAME]"))&" from FC Urban. We organise after-work football for teams in the City and Canary Wharf."&CHAR(10)&CHAR(10)&"We have a "&AE9&" pitch at "&Z9&", "&IF(OR(AA9=8,AA9=11,AA9=18),"an ","a ")&AA9&"-minute walk from your "&P9&" office, "&IF(ISNUMBER(AD9),"on "&TEXT(AD9,"dddd d mmmm")&" at "&TEXT(AD9,"hh:mm"),"on a weekday evening that suits your team")&". It's "&IF(AF9<>"","£"&IF(AF9=INT(AF9),TEXT(AF9,"0"),TEXT(AF9,"0.00")),"[PRICE PER PLAYER]")&" a player and we handle the pitch booking, sign-ups and payments, so all it takes is one person sharing a link with the team."&CHAR(10)&CHAR(10)&"It works well as a team social or "&IF(ISNUMBER(SEARCH(LEFT(F9,1),"AEIOU")),"an ","a ")&F9&" vs clients game. Would your team be up for it, or is there someone who'd enjoy organising it?"&IF(Offer!$C$7<>""," Spots are held until "&TEXT(Offer!$C$7,"dddd d mmmm")&".","")&" "&IF(Offer!$C$6<>"",Offer!$C$6,"[JOINING LINK]")&CHAR(10)&CHAR(10)&"Best,"&CHAR(10)&IF(AM9<>"",AM9,IF(Offer!$C$5<>"",Offer!$C$5,"[NAME]"))&CHAR(10)&"FC Urban" | AK9: ="Hi "&IF(R9<>"",R9,F9&" team")&","&CHAR(10)&CHAR(10)&"Just bumping this up. The "&AE9&" pitch at "&Z9&" is still free "&IF(ISNUMBER(AD9),TEXT(AD9,"ddd d mmm")&", "&TEXT(AD9,"hh:mm"),"weekday evenings")&", "&IF(OR(AA9=8,AA9=11,AA9=18),"an ","a ")&AA9&"-minute walk from your office, "&IF(AF9<>"","£"&IF(AF9=INT(AF9),TEXT(AF9,"0"),TEXT(AF9,"0.00")),"[PRICE PER PLAYER]")&" a player. Happy to hold it for "&F9&" if someone on the team fancies organising a game."&IF(Offer!$C$7<>""," Spots are held until "&TEXT(Offer!$C$7,"dddd d mmmm")&".","")&" "&IF(Offer!$C$6<>"",Offer!$C$6,"[JOINING LINK]")&CHAR(10)&CHAR(10)&"Best,"&CHAR(10)&IF(AM9<>"",AM9,IF(Offer!$C$5<>"",Offer!$C$5,"[NAME]"))&CHAR(10)&"FC Urban" | AL9: =IF(AH9="","No email yet",IF(ISNUMBER(SEARCH("[",AJ9)),"Fill placeholders",IF(ISNUMBER(AD9),"Ready to send","Ready · no fixed slot")))
A10: 8 | B10: 1 | C10: Law firm | D10: City of London | E10: Goodwin Procter (UK) LLP | F10: Goodwin Procter | G10: https://www.goodwinlaw.com | H10: etan@goodwinlaw.com | I10: named person | J10: Open page | K10: OC362294 | L10: Open | M10: Group | N10: 40603 | O10: Sancroft, Newgate Street, London | P10: EC1A 7AZ | Q10: No | W10: City of London School (EC4V 3AL) | X10: 9 | Z10: City of London School (EC4V 3AL) | AA10: 9 | AB10: =IFERROR(INDEX(Venues!$E$2:$E$17,MATCH(Z10,Venues!$A$2:$A$17,0)),"Not checked") | AC10: =IFERROR(INDEX(Venues!$F$2:$F$17,MATCH(Z10,Venues!$A$2:$A$17,0)),0) | AD10: =IFERROR(INDEX(Venues!$M$2:$M$17,MATCH(Z10,Venues!$A$2:$A$17,0)),"") | AE10: =IFERROR(INDEX(Venues!$N$2:$N$17,MATCH(Z10,Venues!$A$2:$A$17,0)),"5-a-side") | AF10: =IF(Offer!$C$4="","",Offer!$C$4) | AG10: =Z10&" ("&AA10&" min walk) · "&IF(ISNUMBER(AD10),TEXT(AD10,"ddd d mmm, hh:mm"),"slot to confirm with venue")&" · "&AE10&" · "&IF(AF10<>"","£"&TEXT(AF10,"0.00")&" pp","price TBC") | AH10: =IF(U10<>"",U10,IF(H10<>"",H10,"")) | AI10: ="After-work football for "&F10&" · "&Z10&", "&AA10&" min from your office" | AJ10: ="Hi "&IF(R10<>"",R10,F10&" team")&","&CHAR(10)&CHAR(10)&"I'm "&IF(AM10<>"",AM10,IF(Offer!$C$5<>"",Offer!$C$5,"[NAME]"))&" from FC Urban. We organise after-work football for teams in the City and Canary Wharf."&CHAR(10)&CHAR(10)&"We have a "&AE10&" pitch at "&Z10&", "&IF(OR(AA10=8,AA10=11,AA10=18),"an ","a ")&AA10&"-minute walk from your "&P10&" office, "&IF(ISNUMBER(AD10),"on "&TEXT(AD10,"dddd d mmmm")&" at "&TEXT(AD10,"hh:mm"),"on a weekday evening that suits your team")&". It's "&IF(AF10<>"","£"&IF(AF10=INT(AF10),TEXT(AF10,"0"),TEXT(AF10,"0.00")),"[PRICE PER PLAYER]")&" a player and we handle the pitch booking, sign-ups and payments, so all it takes is one person sharing a link with the team."&CHAR(10)&CHAR(10)&"It works well as a team social or "&IF(ISNUMBER(SEARCH(LEFT(F10,1),"AEIOU")),"an ","a ")&F10&" vs clients game. Would your team be up for it, or is there someone who'd enjoy organising it?"&IF(Offer!$C$7<>""," Spots are held until "&TEXT(Offer!$C$7,"dddd d mmmm")&".","")&" "&IF(Offer!$C$6<>"",Offer!$C$6,"[JOINING LINK]")&CHAR(10)&CHAR(10)&"Best,"&CHAR(10)&IF(AM10<>"",AM10,IF(Offer!$C$5<>"",Offer!$C$5,"[NAME]"))&CHAR(10)&"FC Urban" | AK10: ="Hi "&IF(R10<>"",R10,F10&" team")&","&CHAR(10)&CHAR(10)&"Just bumping this up. The "&AE10&" pitch at "&Z10&" is still free "&IF(ISNUMBER(AD10),TEXT(AD10,"ddd d mmm")&", "&TEXT(AD10,"hh:mm"),"weekday evenings")&", "&IF(OR(AA10=8,AA10=11,AA10=18),"an ","a ")&AA10&"-minute walk from your office, "&IF(AF10<>"","£"&IF(AF10=INT(AF10),TEXT(AF10,"0"),TEXT(AF10,"0.00")),"[PRICE PER PLAYER]")&" a player. Happy to hold it for "&F10&" if someone on the team fancies organising a game."&IF(Offer!$C$7<>""," Spots are held until "&TEXT(Offer!$C$7,"dddd d mmmm")&".","")&" "&IF(Offer!$C$6<>"",Offer!$C$6,"[JOINING LINK]")&CHAR(10)&CHAR(10)&"Best,"&CHAR(10)&IF(AM10<>"",AM10,IF(Offer!$C$5<>"",Offer!$C$5,"[NAME]"))&CHAR(10)&"FC Urban" | AL10: =IF(AH10="","No email yet",IF(ISNUMBER(SEARCH("[",AJ10)),"Fill placeholders",IF(ISNUMBER(AD10),"Ready to send","Ready · no fixed slot")))
A11: 9 | B11: 1 | C11: Law firm | D11: City of London | E11: Withers LLP | F11: Withers | G11: https://www.withersworldwide.com | H11: hello@withersworldwide.com | I11: general | J11: Open page | K11: OC301149 | L11: Open | M11: Group | N11: 37238 | O11: Third Floor, 20 Old Bailey, London | P11: EC4M 7AN | Q11: No | W11: City of London School (EC4V 3AL) | X11: 9 | Z11: City of London School (EC4V 3AL) | AA11: 9 | AB11: =IFERROR(INDEX(Venues!$E$2:$E$17,MATCH(Z11,Venues!$A$2:$A$17,0)),"Not checked") | AC11: =IFERROR(INDEX(Venues!$F$2:$F$17,MATCH(Z11,Venues!$A$2:$A$17,0)),0) | AD11: =IFERROR(INDEX(Venues!$M$2:$M$17,MATCH(Z11,Venues!$A$2:$A$17,0)),"") | AE11: =IFERROR(INDEX(Venues!$N$2:$N$17,MATCH(Z11,Venues!$A$2:$A$17,0)),"5-a-side") | AF11: =IF(Offer!$C$4="","",Offer!$C$4) | AG11: =Z11&" ("&AA11&" min walk) · "&IF(ISNUMBER(AD11),TEXT(AD11,"ddd d mmm, hh:mm"),"slot to confirm with venue")&" · "&AE11&" · "&IF(AF11<>"","£"&TEXT(AF11,"0.00")&" pp","price TBC") | AH11: =IF(U11<>"",U11,IF(H11<>"",H11,"")) | AI11: ="After-work football for "&F11&" · "&Z11&", "&AA11&" min from your office" | AJ11: ="Hi "&IF(R11<>"",R11,F11&" team")&","&CHAR(10)&CHAR(10)&"I'm "&IF(AM11<>"",AM11,IF(Offer!$C$5<>"",Offer!$C$5,"[NAME]"))&" from FC Urban. We organise after-work football for teams in the City and Canary Wharf."&CHAR(10)&CHAR(10)&"We have a "&AE11&" pitch at "&Z11&", "&IF(OR(AA11=8,AA11=11,AA11=18),"an ","a ")&AA11&"-minute walk from your "&P11&" office, "&IF(ISNUMBER(AD11),"on "&TEXT(AD11,"dddd d mmmm")&" at "&TEXT(AD11,"hh:mm"),"on a weekday evening that suits your team")&". It's "&IF(AF11<>"","£"&IF(AF11=INT(AF11),TEXT(AF11,"0"),TEXT(AF11,"0.00")),"[PRICE PER PLAYER]")&" a player and we handle the pitch booking, sign-ups and payments, so all it takes is one person sharing a link with the team."&CHAR(10)&CHAR(10)&"It works well as a team social or "&IF(ISNUMBER(SEARCH(LEFT(F11,1),"AEIOU")),"an ","a ")&F11&" vs clients game. Would your team be up for it, or is there someone who'd enjoy organising it?"&IF(Offer!$C$7<>""," Spots are held until "&TEXT(Offer!$C$7,"dddd d mmmm")&".","")&" "&IF(Offer!$C$6<>"",Offer!$C$6,"[JOINING LINK]")&CHAR(10)&CHAR(10)&"Best,"&CHAR(10)&IF(AM11<>"",AM11,IF(Offer!$C$5<>"",Offer!$C$5,"[NAME]"))&CHAR(10)&"FC Urban" | AK11: ="Hi "&IF(R11<>"",R11,F11&" team")&","&CHAR(10)&CHAR(10)&"Just bumping this up. The "&AE11&" pitch at "&Z11&" is still free "&IF(ISNUMBER(AD11),TEXT(AD11,"ddd d mmm")&", "&TEXT(AD11,"hh:mm"),"weekday evenings")&", "&IF(OR(AA11=8,AA11=11,AA11=18),"an ","a ")&AA11&"-minute walk from your office, "&IF(AF11<>"","£"&IF(AF11=INT(AF11),TEXT(AF11,"0"),TEXT(AF11,"0.00")),"[PRICE PER PLAYER]")&" a player. Happy to hold it for "&F11&" if someone on the team fancies organising a game."&IF(Offer!$C$7<>""," Spots are held until "&TEXT(Offer!$C$7,"dddd d mmmm")&".","")&" "&IF(Offer!$C$6<>"",Offer!$C$6,"[JOINING LINK]")&CHAR(10)&CHAR(10)&"Best,"&CHAR(10)&IF(AM11<>"",AM11,IF(Offer!$C$5<>"",Offer!$C$5,"[NAME]"))&CHAR(10)&"FC Urban" | AL11: =IF(AH11="","No email yet",IF(ISNUMBER(SEARCH("[",AJ11)),"Fill placeholders",IF(ISNUMBER(AD11),"Ready to send","Ready · no fixed slot")))
A12: 10 | B12: 1 | C12: Law firm | D12: City of London | E12: Charles Russell Speechlys LLP | F12: Charles Russell Speechlys | G12: https://www.charlesrussellspeechlys.com | H12: london@charlesrussellspeechlys.com | I12: general | J12: Open page | K12: OC311850 | L12: Open | M12: Group | N12: 38407 | O12: 5 Fleet Place, London | P12: EC4M 7RD | Q12: No | W12: City of London School (EC4V 3AL) | X12: 9 | Z12: City of London School (EC4V 3AL) | AA12: 9 | AB12: =IFERROR(INDEX(Venues!$E$2:$E$17,MATCH(Z12,Venues!$A$2:$A$17,0)),"Not checked") | AC12: =IFERROR(INDEX(Venues!$F$2:$F$17,MATCH(Z12,Venues!$A$2:$A$17,0)),0) | AD12: =IFERROR(INDEX(Venues!$M$2:$M$17,MATCH(Z12,Venues!$A$2:$A$17,0)),"") | AE12: =IFERROR(INDEX(Venues!$N$2:$N$17,MATCH(Z12,Venues!$A$2:$A$17,0)),"5-a-side") | AF12: =IF(Offer!$C$4="","",Offer!$C$4) | AG12: =Z12&" ("&AA12&" min walk) · "&IF(ISNUMBER(AD12),TEXT(AD12,"ddd d mmm, hh:mm"),"slot to confirm with venue")&" · "&AE12&" · "&IF(AF12<>"","£"&TEXT(AF12,"0.00")&" pp","price TBC") | AH12: =IF(U12<>"",U12,IF(H12<>"",H12,"")) | AI12: ="After-work football for "&F12&" · "&Z12&", "&AA12&" min from your office" | AJ12: ="Hi "&IF(R12<>"",R12,F12&" team")&","&CHAR(10)&CHAR(10)&"I'm "&IF(AM12<>"",AM12,IF(Offer!$C$5<>"",Offer!$C$5,"[NAME]"))&" from FC Urban. We organise after-work football for teams in the City and Canary Wharf."&CHAR(10)&CHAR(10)&"We have a "&AE12&" pitch at "&Z12&", "&IF(OR(AA12=8,AA12=11,AA12=18),"an ","a ")&AA12&"-minute walk from your "&P12&" office, "&IF(ISNUMBER(AD12),"on "&TEXT(AD12,"dddd d mmmm")&" at "&TEXT(AD12,"hh:mm"),"on a weekday evening that suits your team")&". It's "&IF(AF12<>"","£"&IF(AF12=INT(AF12),TEXT(AF12,"0"),TEXT(AF12,"0.00")),"[PRICE PER PLAYER]")&" a player and we handle the pitch booking, sign-ups and payments, so all it takes is one person sharing a link with the team."&CHAR(10)&CHAR(10)&"It works well as a team social or "&IF(ISNUMBER(SEARCH(LEFT(F12,1),"AEIOU")),"an ","a ")&F12&" vs clients game. Would your team be up for it, or is there someone who'd enjoy organising it?"&IF(Offer!$C$7<>""," Spots are held until "&TEXT(Offer!$C$7,"dddd d mmmm")&".","")&" "&IF(Offer!$C$6<>"",Offer!$C$6,"[JOINING LINK]")&CHAR(10)&CHAR(10)&"Best,"&CHAR(10)&IF(AM12<>"",AM12,IF(Offer!$C$5<>"",Offer!$C$5,"[NAME]"))&CHAR(10)&"FC Urban" | AK12: ="Hi "&IF(R12<>"",R12,F12&" team")&","&CHAR(10)&CHAR(10)&"Just bumping this up. The "&AE12&" pitch at "&Z12&" is still free "&IF(ISNUMBER(AD12),TEXT(AD12,"ddd d mmm")&", "&TEXT(AD12,"hh:mm"),"weekday evenings")&", "&IF(OR(AA12=8,AA12=11,AA12=18),"an ","a ")&AA12&"-minute walk from your office, "&IF(AF12<>"","£"&IF(AF12=INT(AF12),TEXT(AF12,"0"),TEXT(AF12,"0.00")),"[PRICE PER PLAYER]")&" a player. Happy to hold it for "&F12&" if someone on the team fancies organising a game."&IF(Offer!$C$7<>""," Spots are held until "&TEXT(Offer!$C$7,"dddd d mmmm")&".","")&" "&IF(Offer!$C$6<>"",Offer!$C$6,"[JOINING LINK]")&CHAR(10)&CHAR(10)&"Best,"&CHAR(10)&IF(AM12<>"",AM12,IF(Offer!$C$5<>"",Offer!$C$5,"[NAME]"))&CHAR(10)&"FC Urban" | AL12: =IF(AH12="","No email yet",IF(ISNUMBER(SEARCH("[",AJ12)),"Fill placeholders",IF(ISNUMBER(AD12),"Ready to send","Ready · no fixed slot")))
A13: 11 | B13: 1 | C13: Law firm | D13: City of London | E13: CMS Cameron McKenna Nabarro Olswang LLP | F13: CMS Cameron McKenna Nabarro Olswang | G13: https://cms.law | I13: Not found | K13: OC310335 | L13: Open | M13: Group | N13: 38323 | O13: Cannon Place, 78 Cannon Street, London | P13: EC4N 6AF | Q13: No | W13: City of London School (EC4V 3AL) | X13: 10 | Y13: Marlborough Sports Garden (SE1 1SD) (14.7) | Z13: City of London School (EC4V 3AL) | AA13: 10 | AB13: =IFERROR(INDEX(Venues!$E$2:$E$17,MATCH(Z13,Venues!$A$2:$A$17,0)),"Not checked") | AC13: =IFERROR(INDEX(Venues!$F$2:$F$17,MATCH(Z13,Venues!$A$2:$A$17,0)),0) | AD13: =IFERROR(INDEX(Venues!$M$2:$M$17,MATCH(Z13,Venues!$A$2:$A$17,0)),"") | AE13: =IFERROR(INDEX(Venues!$N$2:$N$17,MATCH(Z13,Venues!$A$2:$A$17,0)),"5-a-side") | AF13: =IF(Offer!$C$4="","",Offer!$C$4) | AG13: =Z13&" ("&AA13&" min walk) · "&IF(ISNUMBER(AD13),TEXT(AD13,"ddd d mmm, hh:mm"),"slot to confirm with venue")&" · "&AE13&" · "&IF(AF13<>"","£"&TEXT(AF13,"0.00")&" pp","price TBC") | AH13: =IF(U13<>"",U13,IF(H13<>"",H13,"")) | AI13: ="After-work football for "&F13&" · "&Z13&", "&AA13&" min from your office" | AJ13: ="Hi "&IF(R13<>"",R13,F13&" team")&","&CHAR(10)&CHAR(10)&"I'm "&IF(AM13<>"",AM13,IF(Offer!$C$5<>"",Offer!$C$5,"[NAME]"))&" from FC Urban. We organise after-work football for teams in the City and Canary Wharf."&CHAR(10)&CHAR(10)&"We have a "&AE13&" pitch at "&Z13&", "&IF(OR(AA13=8,AA13=11,AA13=18),"an ","a ")&AA13&"-minute walk from your "&P13&" office, "&IF(ISNUMBER(AD13),"on "&TEXT(AD13,"dddd d mmmm")&" at "&TEXT(AD13,"hh:mm"),"on a weekday evening that suits your team")&". It's "&IF(AF13<>"","£"&IF(AF13=INT(AF13),TEXT(AF13,"0"),TEXT(AF13,"0.00")),"[PRICE PER PLAYER]")&" a player and we handle the pitch booking, sign-ups and payments, so all it takes is one person sharing a link with the team."&CHAR(10)&CHAR(10)&"It works well as a team social or "&IF(ISNUMBER(SEARCH(LEFT(F13,1),"AEIOU")),"an ","a ")&F13&" vs clients game. Would your team be up for it, or is there someone who'd enjoy organising it?"&IF(Offer!$C$7<>""," Spots are held until "&TEXT(Offer!$C$7,"dddd d mmmm")&".","")&" "&IF(Offer!$C$6<>"",Offer!$C$6,"[JOINING LINK]")&CHAR(10)&CHAR(10)&"Best,"&CHAR(10)&IF(AM13<>"",AM13,IF(Offer!$C$5<>"",Offer!$C$5,"[NAME]"))&CHAR(10)&"FC Urban" | AK13: ="Hi "&IF(R13<>"",R13,F13&" team")&","&CHAR(10)&CHAR(10)&"Just bumping this up. The "&AE13&" pitch at "&Z13&" is still free "&IF(ISNUMBER(AD13),TEXT(AD13,"ddd d mmm")&", "&TEXT(AD13,"hh:mm"),"weekday evenings")&", "&IF(OR(AA13=8,AA13=11,AA13=18),"an ","a ")&AA13&"-minute walk from your office, "&IF(AF13<>"","£"&IF(AF13=INT(AF13),TEXT(AF13,"0"),TEXT(AF13,"0.00")),"[PRICE PER PLAYER]")&" a player. Happy to hold it for "&F13&" if someone on the team fancies organising a game."&IF(Offer!$C$7<>""," Spots are held until "&TEXT(Offer!$C$7,"dddd d mmmm")&".","")&" "&IF(Offer!$C$6<>"",Offer!$C$6,"[JOINING LINK]")&CHAR(10)&CHAR(10)&"Best,"&CHAR(10)&IF(AM13<>"",AM13,IF(Offer!$C$5<>"",Offer!$C$5,"[NAME]"))&CHAR(10)&"FC Urban" | AL13: =IF(AH13="","No email yet",IF(ISNUMBER(SEARCH("[",AJ13)),"Fill placeholders",IF(ISNUMBER(AD13),"Ready to send","Ready · no fixed slot")))
A14: 12 | B14: 1 | C14: Law firm | D14: City of London | E14: Bryan Cave Leighton Paisner LLP | F14: Bryan Cave Leighton Paisner | G14: https://www.bclplaw.com | H14: kwfries@bclplaw.com | I14: named person | J14: Open page | K14: OC315919 | L14: Open | M14: Group | N14: 38657 | O14: Governor'S House, 5 Laurence Pountney Hill, London | P14: EC4R 0BR | Q14: No | W14: City of London School (EC4V 3AL) | X14: 12 | Y14: Marlborough Sports Garden (SE1 1SD) (13.4) | Z14: City of London School (EC4V 3AL) | AA14: 12 | AB14: =IFERROR(INDEX(Venues!$E$2:$E$17,MATCH(Z14,Venues!$A$2:$A$17,0)),"Not checked") | AC14: =IFERROR(INDEX(Venues!$F$2:$F$17,MATCH(Z14,Venues!$A$2:$A$17,0)),0) | AD14: =IFERROR(INDEX(Venues!$M$2:$M$17,MATCH(Z14,Venues!$A$2:$A$17,0)),"") | AE14: =IFERROR(INDEX(Venues!$N$2:$N$17,MATCH(Z14,Venues!$A$2:$A$17,0)),"5-a-side") | AF14: =IF(Offer!$C$4="","",Offer!$C$4) | AG14: =Z14&" ("&AA14&" min walk) · "&IF(ISNUMBER(AD14),TEXT(AD14,"ddd d mmm, hh:mm"),"slot to confirm with venue")&" · "&AE14&" · "&IF(AF14<>"","£"&TEXT(AF14,"0.00")&" pp","price TBC") | AH14: =IF(U14<>"",U14,IF(H14<>"",H14,"")) | AI14: ="After-work football for "&F14&" · "&Z14&", "&AA14&" min from your office" | AJ14: ="Hi "&IF(R14<>"",R14,F14&" team")&","&CHAR(10)&CHAR(10)&"I'm "&IF(AM14<>"",AM14,IF(Offer!$C$5<>"",Offer!$C$5,"[NAME]"))&" from FC Urban. We organise after-work football for teams in the City and Canary Wharf."&CHAR(10)&CHAR(10)&"We have a "&AE14&" pitch at "&Z14&", "&IF(OR(AA14=8,AA14=11,AA14=18),"an ","a ")&AA14&"-minute walk from your "&P14&" office, "&IF(ISNUMBER(AD14),"on "&TEXT(AD14,"dddd d mmmm")&" at "&TEXT(AD14,"hh:mm"),"on a weekday evening that suits your team")&". It's "&IF(AF14<>"","£"&IF(AF14=INT(AF14),TEXT(AF14,"0"),TEXT(AF14,"0.00")),"[PRICE PER PLAYER]")&" a player and we handle the pitch booking, sign-ups and payments, so all it takes is one person sharing a link with the team."&CHAR(10)&CHAR(10)&"It works well as a team social or "&IF(ISNUMBER(SEARCH(LEFT(F14,1),"AEIOU")),"an ","a ")&F14&" vs clients game. Would your team be up for it, or is there someone who'd enjoy organising it?"&IF(Offer!$C$7<>""," Spots are held until "&TEXT(Offer!$C$7,"dddd d mmmm")&".","")&" "&IF(Offer!$C$6<>"",Offer!$C$6,"[JOINING LINK]")&CHAR(10)&CHAR(10)&"Best,"&CHAR(10)&IF(AM14<>"",AM14,IF(Offer!$C$5<>"",Offer!$C$5,"[NAME]"))&CHAR(10)&"FC Urban" | AK14: ="Hi "&IF(R14<>"",R14,F14&" team")&","&CHAR(10)&CHAR(10)&"Just bumping this up. The "&AE14&" pitch at "&Z14&" is still free "&IF(ISNUMBER(AD14),TEXT(AD14,"ddd d mmm")&", "&TEXT(AD14,"hh:mm"),"weekday evenings")&", "&IF(OR(AA14=8,AA14=11,AA14=18),"an ","a ")&AA14&"-minute walk from your office, "&IF(AF14<>"","£"&IF(AF14=INT(AF14),TEXT(AF14,"0"),TEXT(AF14,"0.00")),"[PRICE PER PLAYER]")&" a player. Happy to hold it for "&F14&" if someone on the team fancies organising a game."&IF(Offer!$C$7<>""," Spots are held until "&TEXT(Offer!$C$7,"dddd d mmmm")&".","")&" "&IF(Offer!$C$6<>"",Offer!$C$6,"[JOINING LINK]")&CHAR(10)&CHAR(10)&"Best,"&CHAR(10)&IF(AM14<>"",AM14,IF(Offer!$C$5<>"",Offer!$C$5,"[NAME]"))&CHAR(10)&"FC Urban" | AL14: =IF(AH14="","No email yet",IF(ISNUMBER(SEARCH("[",AJ14)),"Fill placeholders",IF(ISNUMBER(AD14),"Ready to send","Ready · no fixed slot")))
A15: 13 | B15: 1 | C15: Law firm | D15: City of London | E15: Osborne Clarke LLP | F15: Osborne Clarke | G15: https://www.osborneclarke.com | H15: luis.gil@osborneclarke.com | I15: named person | J15: Open page | K15: OC397443 | L15: Open | M15: Group | N15: 42016 | O15: One London Wall, London | P15: EC2Y 5EB | Q15: No | W15: City of London School (EC4V 3AL) | X15: 12 | Y15: Finsbury Leisure Centre (EC1V 3PU) (16) | Z15: City of London School (EC4V 3AL) | AA15: 12 | AB15: =IFERROR(INDEX(Venues!$E$2:$E$17,MATCH(Z15,Venues!$A$2:$A$17,0)),"Not checked") | AC15: =IFERROR(INDEX(Venues!$F$2:$F$17,MATCH(Z15,Venues!$A$2:$A$17,0)),0) | AD15: =IFERROR(INDEX(Venues!$M$2:$M$17,MATCH(Z15,Venues!$A$2:$A$17,0)),"") | AE15: =IFERROR(INDEX(Venues!$N$2:$N$17,MATCH(Z15,Venues!$A$2:$A$17,0)),"5-a-side") | AF15: =IF(Offer!$C$4="","",Offer!$C$4) | AG15: =Z15&" ("&AA15&" min walk) · "&IF(ISNUMBER(AD15),TEXT(AD15,"ddd d mmm, hh:mm"),"slot to confirm with venue")&" · "&AE15&" · "&IF(AF15<>"","£"&TEXT(AF15,"0.00")&" pp","price TBC") | AH15: =IF(U15<>"",U15,IF(H15<>"",H15,"")) | AI15: ="After-work football for "&F15&" · "&Z15&", "&AA15&" min from your office" | AJ15: ="Hi "&IF(R15<>"",R15,F15&" team")&","&CHAR(10)&CHAR(10)&"I'm "&IF(AM15<>"",AM15,IF(Offer!$C$5<>"",Offer!$C$5,"[NAME]"))&" from FC Urban. We organise after-work football for teams in the City and Canary Wharf."&CHAR(10)&CHAR(10)&"We have a "&AE15&" pitch at "&Z15&", "&IF(OR(AA15=8,AA15=11,AA15=18),"an ","a ")&AA15&"-minute walk from your "&P15&" office, "&IF(ISNUMBER(AD15),"on "&TEXT(AD15,"dddd d mmmm")&" at "&TEXT(AD15,"hh:mm"),"on a weekday evening that suits your team")&". It's "&IF(AF15<>"","£"&IF(AF15=INT(AF15),TEXT(AF15,"0"),TEXT(AF15,"0.00")),"[PRICE PER PLAYER]")&" a player and we handle the pitch booking, sign-ups and payments, so all it takes is one person sharing a link with the team."&CHAR(10)&CHAR(10)&"It works well as a team social or "&IF(ISNUMBER(SEARCH(LEFT(F15,1),"AEIOU")),"an ","a ")&F15&" vs clients game. Would your team be up for it, or is there someone who'd enjoy organising it?"&IF(Offer!$C$7<>""," Spots are held until "&TEXT(Offer!$C$7,"dddd d mmmm")&".","")&" "&IF(Offer!$C$6<>"",Offer!$C$6,"[JOINING LINK]")&CHAR(10)&CHAR(10)&"Best,"&CHAR(10)&IF(AM15<>"",AM15,IF(Offer!$C$5<>"",Offer!$C$5,"[NAME]"))&CHAR(10)&"FC Urban" | AK15: ="Hi "&IF(R15<>"",R15,F15&" team")&","&CHAR(10)&CHAR(10)&"Just bumping this up. The "&AE15&" pitch at "&Z15&" is still free "&IF(ISNUMBER(AD15),TEXT(AD15,"ddd d mmm")&", "&TEXT(AD15,"hh:mm"),"weekday evenings")&", "&IF(OR(AA15=8,AA15=11,AA15=18),"an ","a ")&AA15&"-minute walk from your office, "&IF(AF15<>"","£"&IF(AF15=INT(AF15),TEXT(AF15,"0"),TEXT(AF15,"0.00")),"[PRICE PER PLAYER]")&" a player. Happy to hold it for "&F15&" if someone on the team fancies organising a game."&IF(Offer!$C$7<>""," Spots are held until "&TEXT(Offer!$C$7,"dddd d mmmm")&".","")&" "&IF(Offer!$C$6<>"",Offer!$C$6,"[JOINING LINK]")&CHAR(10)&CHAR(10)&"Best,"&CHAR(10)&IF(AM15<>"",AM15,IF(Offer!$C$5<>"",Offer!$C$5,"[NAME]"))&CHAR(10)&"FC Urban" | AL15: =IF(AH15="","No email yet",IF(ISNUMBER(SEARCH("[",AJ15)),"Fill placeholders",IF(ISNUMBER(AD15),"Ready to send","Ready · no fixed slot")))
A16: 14 | B16: 1 | C16: Law firm | D16: City of London | E16: Fragomen (GB) Limited | F16: Fragomen | G16: https://www.fragomen.com | H16: london@fragomen.com | I16: general | J16: Open page | K16: 04732334 | L16: Open | M16: Group | N16: 37724 | O16: 95 Gresham Street, 1St Floor, London | P16: EC2V 7NA | Q16: No | W16: City of London School (EC4V 3AL) | X16: 12 | Z16: City of London School (EC4V 3AL) | AA16: 12 | AB16: =IFERROR(INDEX(Venues!$E$2:$E$17,MATCH(Z16,Venues!$A$2:$A$17,0)),"Not checked") | AC16: =IFERROR(INDEX(Venues!$F$2:$F$17,MATCH(Z16,Venues!$A$2:$A$17,0)),0) | AD16: =IFERROR(INDEX(Venues!$M$2:$M$17,MATCH(Z16,Venues!$A$2:$A$17,0)),"") | AE16: =IFERROR(INDEX(Venues!$N$2:$N$17,MATCH(Z16,Venues!$A$2:$A$17,0)),"5-a-side") | AF16: =IF(Offer!$C$4="","",Offer!$C$4) | AG16: =Z16&" ("&AA16&" min walk) · "&IF(ISNUMBER(AD16),TEXT(AD16,"ddd d mmm, hh:mm"),"slot to confirm with venue")&" · "&AE16&" · "&IF(AF16<>"","£"&TEXT(AF16,"0.00")&" pp","price TBC") | AH16: =IF(U16<>"",U16,IF(H16<>"",H16,"")) | AI16: ="After-work football for "&F16&" · "&Z16&", "&AA16&" min from your office" | AJ16: ="Hi "&IF(R16<>"",R16,F16&" team")&","&CHAR(10)&CHAR(10)&"I'm "&IF(AM16<>"",AM16,IF(Offer!$C$5<>"",Offer!$C$5,"[NAME]"))&" from FC Urban. We organise after-work football for teams in the City and Canary Wharf."&CHAR(10)&CHAR(10)&"We have a "&AE16&" pitch at "&Z16&", "&IF(OR(AA16=8,AA16=11,AA16=18),"an ","a ")&AA16&"-minute walk from your "&P16&" office, "&IF(ISNUMBER(AD16),"on "&TEXT(AD16,"dddd d mmmm")&" at "&TEXT(AD16,"hh:mm"),"on a weekday evening that suits your team")&". It's "&IF(AF16<>"","£"&IF(AF16=INT(AF16),TEXT(AF16,"0"),TEXT(AF16,"0.00")),"[PRICE PER PLAYER]")&" a player and we handle the pitch booking, sign-ups and payments, so all it takes is one person sharing a link with the team."&CHAR(10)&CHAR(10)&"It works well as a team social or "&IF(ISNUMBER(SEARCH(LEFT(F16,1),"AEIOU")),"an ","a ")&F16&" vs clients game. Would your team be up for it, or is there someone who'd enjoy organising it?"&IF(Offer!$C$7<>""," Spots are held until "&TEXT(Offer!$C$7,"dddd d mmmm")&".","")&" "&IF(Offer!$C$6<>"",Offer!$C$6,"[JOINING LINK]")&CHAR(10)&CHAR(10)&"Best,"&CHAR(10)&IF(AM16<>"",AM16,IF(Offer!$C$5<>"",Offer!$C$5,"[NAME]"))&CHAR(10)&"FC Urban" | AK16: ="Hi "&IF(R16<>"",R16,F16&" team")&","&CHAR(10)&CHAR(10)&"Just bumping this up. The "&AE16&" pitch at "&Z16&" is still free "&IF(ISNUMBER(AD16),TEXT(AD16,"ddd d mmm")&", "&TEXT(AD16,"hh:mm"),"weekday evenings")&", "&IF(OR(AA16=8,AA16=11,AA16=18),"an ","a ")&AA16&"-minute walk from your office, "&IF(AF16<>"","£"&IF(AF16=INT(AF16),TEXT(AF16,"0"),TEXT(AF16,"0.00")),"[PRICE PER PLAYER]")&" a player. Happy to hold it for "&F16&" if someone on the team fancies organising a game."&IF(Offer!$C$7<>""," Spots are held until "&TEXT(Offer!$C$7,"dddd d mmmm")&".","")&" "&IF(Offer!$C$6<>"",Offer!$C$6,"[JOINING LINK]")&CHAR(10)&CHAR(10)&"Best,"&CHAR(10)&IF(AM16<>"",AM16,IF(Offer!$C$5<>"",Offer!$C$5,"[NAME]"))&CHAR(10)&"FC Urban" | AL16: =IF(AH16="","No email yet",IF(ISNUMBER(SEARCH("[",AJ16)),"Fill placeholders",IF(ISNUMBER(AD16),"Ready to send","Ready · no fixed slot")))
A17: 15 | B17: 1 | C17: Law firm | D17: City of London | E17: Fieldfisher LLP | F17: Fieldfisher | G17: https://www.fieldfisher.com | H17: london@fieldfisher.com | I17: general | J17: Open page | K17: OC318472 | L17: Open | M17: Group | N17: 38792 | O17: Riverbank House, 2 Swan Lane, London | P17: EC4R 3TT | Q17: No | W17: City of London School (EC4V 3AL) | X17: 12 | Y17: Marlborough Sports Garden (SE1 1SD) (12.4) | Z17: City of London School (EC4V 3AL) | AA17: 12 | AB17: =IFERROR(INDEX(Venues!$E$2:$E$17,MATCH(Z17,Venues!$A$2:$A$17,0)),"Not checked") | AC17: =IFERROR(INDEX(Venues!$F$2:$F$17,MATCH(Z17,Venues!$A$2:$A$17,0)),0) | AD17: =IFERROR(INDEX(Venues!$M$2:$M$17,MATCH(Z17,Venues!$A$2:$A$17,0)),"") | AE17: =IFERROR(INDEX(Venues!$N$2:$N$17,MATCH(Z17,Venues!$A$2:$A$17,0)),"5-a-side") | AF17: =IF(Offer!$C$4="","",Offer!$C$4) | AG17: =Z17&" ("&AA17&" min walk) · "&IF(ISNUMBER(AD17),TEXT(AD17,"ddd d mmm, hh:mm"),"slot to confirm with venue")&" · "&AE17&" · "&IF(AF17<>"","£"&TEXT(AF17,"0.00")&" pp","price TBC") | AH17: =IF(U17<>"",U17,IF(H17<>"",H17,"")) | AI17: ="After-work football for "&F17&" · "&Z17&", "&AA17&" min from your office" | AJ17: ="Hi "&IF(R17<>"",R17,F17&" team")&","&CHAR(10)&CHAR(10)&"I'm "&IF(AM17<>"",AM17,IF(Offer!$C$5<>"",Offer!$C$5,"[NAME]"))&" from FC Urban. We organise after-work football for teams in the City and Canary Wharf."&CHAR(10)&CHAR(10)&"We have a "&AE17&" pitch at "&Z17&", "&IF(OR(AA17=8,AA17=11,AA17=18),"an ","a ")&AA17&"-minute walk from your "&P17&" office, "&IF(ISNUMBER(AD17),"on "&TEXT(AD17,"dddd d mmmm")&" at "&TEXT(AD17,"hh:mm"),"on a weekday evening that suits your team")&". It's "&IF(AF17<>"","£"&IF(AF17=INT(AF17),TEXT(AF17,"0"),TEXT(AF17,"0.00")),"[PRICE PER PLAYER]")&" a player and we handle the pitch booking, sign-ups and payments, so all it takes is one person sharing a link with the team."&CHAR(10)&CHAR(10)&"It works well as a team social or "&IF(ISNUMBER(SEARCH(LEFT(F17,1),"AEIOU")),"an ","a ")&F17&" vs clients game. Would your team be up for it, or is there someone who'd enjoy organising it?"&IF(Offer!$C$7<>""," Spots are held until "&TEXT(Offer!$C$7,"dddd d mmmm")&".","")&" "&IF(Offer!$C$6<>"",Offer!$C$6,"[JOINING LINK]")&CHAR(10)&CHAR(10)&"Best,"&CHAR(10)&IF(AM17<>"",AM17,IF(Offer!$C$5<>"",Offer!$C$5,"[NAME]"))&CHAR(10)&"FC Urban" | AK17: ="Hi "&IF(R17<>"",R17,F17&" team")&","&CHAR(10)&CHAR(10)&"Just bumping this up. The "&AE17&" pitch at "&Z17&" is still free "&IF(ISNUMBER(AD17),TEXT(AD17,"ddd d mmm")&", "&TEXT(AD17,"hh:mm"),"weekday evenings")&", "&IF(OR(AA17=8,AA17=11,AA17=18),"an ","a ")&AA17&"-minute walk from your office, "&IF(AF17<>"","£"&IF(AF17=INT(AF17),TEXT(AF17,"0"),TEXT(AF17,"0.00")),"[PRICE PER PLAYER]")&" a player. Happy to hold it for "&F17&" if someone on the team fancies organising a game."&IF(Offer!$C$7<>""," Spots are held until "&TEXT(Offer!$C$7,"dddd d mmmm")&".","")&" "&IF(Offer!$C$6<>"",Offer!$C$6,"[JOINING LINK]")&CHAR(10)&CHAR(10)&"Best,"&CHAR(10)&IF(AM17<>"",AM17,IF(Offer!$C$5<>"",Offer!$C$5,"[NAME]"))&CHAR(10)&"FC Urban" | AL17: =IF(AH17="","No email yet",IF(ISNUMBER(SEARCH("[",AJ17)),"Fill placeholders",IF(ISNUMBER(AD17),"Ready to send","Ready · no fixed slot")))
A18: 16 | B18: 1 | C18: Law firm | D18: City of London | E18: Hogan Lovells Cadwalader International LLP | F18: Hogan Lovells Cadwalader | G18: https://www.hlc.com | H18: connect@hlc.com | I18: named person | J18: Open page | K18: OC323639 | L18: Open | M18: Group | N18: 39023 | O18: Atlantic House, Holborn Viaduct, London | P18: EC1A 2FG | Q18: Yes | W18: City of London School (EC4V 3AL) | X18: 14 | Z18: City of London School (EC4V 3AL) | AA18: 14 | AB18: =IFERROR(INDEX(Venues!$E$2:$E$17,MATCH(Z18,Venues!$A$2:$A$17,0)),"Not checked") | AC18: =IFERROR(INDEX(Venues!$F$2:$F$17,MATCH(Z18,Venues!$A$2:$A$17,0)),0) | AD18: =IFERROR(INDEX(Venues!$M$2:$M$17,MATCH(Z18,Venues!$A$2:$A$17,0)),"") | AE18: =IFERROR(INDEX(Venues!$N$2:$N$17,MATCH(Z18,Venues!$A$2:$A$17,0)),"5-a-side") | AF18: =IF(Offer!$C$4="","",Offer!$C$4) | AG18: =Z18&" ("&AA18&" min walk) · "&IF(ISNUMBER(AD18),TEXT(AD18,"ddd d mmm, hh:mm"),"slot to confirm with venue")&" · "&AE18&" · "&IF(AF18<>"","£"&TEXT(AF18,"0.00")&" pp","price TBC") | AH18: =IF(U18<>"",U18,IF(H18<>"",H18,"")) | AI18: ="After-work football for "&F18&" · "&Z18&", "&AA18&" min from your office" | AJ18: ="Hi "&IF(R18<>"",R18,F18&" team")&","&CHAR(10)&CHAR(10)&"I'm "&IF(AM18<>"",AM18,IF(Offer!$C$5<>"",Offer!$C$5,"[NAME]"))&" from FC Urban. We organise after-work football for teams in the City and Canary Wharf."&CHAR(10)&CHAR(10)&"We have a "&AE18&" pitch at "&Z18&", "&IF(OR(AA18=8,AA18=11,AA18=18),"an ","a ")&AA18&"-minute walk from your "&P18&" office, "&IF(ISNUMBER(AD18),"on "&TEXT(AD18,"dddd d mmmm")&" at "&TEXT(AD18,"hh:mm"),"on a weekday evening that suits your team")&". It's "&IF(AF18<>"","£"&IF(AF18=INT(AF18),TEXT(AF18,"0"),TEXT(AF18,"0.00")),"[PRICE PER PLAYER]")&" a player and we handle the pitch booking, sign-ups and payments, so all it takes is one person sharing a link with the team."&CHAR(10)&CHAR(10)&"It works well as a team social or "&IF(ISNUMBER(SEARCH(LEFT(F18,1),"AEIOU")),"an ","a ")&F18&" vs clients game. Would your team be up for it, or is there someone who'd enjoy organising it?"&IF(Offer!$C$7<>""," Spots are held until "&TEXT(Offer!$C$7,"dddd d mmmm")&".","")&" "&IF(Offer!$C$6<>"",Offer!$C$6,"[JOINING LINK]")&CHAR(10)&CHAR(10)&"Best,"&CHAR(10)&IF(AM18<>"",AM18,IF(Offer!$C$5<>"",Offer!$C$5,"[NAME]"))&CHAR(10)&"FC Urban" | AK18: ="Hi "&IF(R18<>"",R18,F18&" team")&","&CHAR(10)&CHAR(10)&"Just bumping this up. The "&AE18&" pitch at "&Z18&" is still free "&IF(ISNUMBER(AD18),TEXT(AD18,"ddd d mmm")&", "&TEXT(AD18,"hh:mm"),"weekday evenings")&", "&IF(OR(AA18=8,AA18=11,AA18=18),"an ","a ")&AA18&"-minute walk from your office, "&IF(AF18<>"","£"&IF(AF18=INT(AF18),TEXT(AF18,"0"),TEXT(AF18,"0.00")),"[PRICE PER PLAYER]")&" a player. Happy to hold it for "&F18&" if someone on the team fancies organising a game."&IF(Offer!$C$7<>""," Spots are held until "&TEXT(Offer!$C$7,"dddd d mmmm")&".","")&" "&IF(Offer!$C$6<>"",Offer!$C$6,"[JOINING LINK]")&CHAR(10)&CHAR(10)&"Best,"&CHAR(10)&IF(AM18<>"",AM18,IF(Offer!$C$5<>"",Offer!$C$5,"[NAME]"))&CHAR(10)&"FC Urban" | AL18: =IF(AH18="","No email yet",IF(ISNUMBER(SEARCH("[",AJ18)),"Fill placeholders",IF(ISNUMBER(AD18),"Ready to send","Ready · no fixed slot")))
A19: 17 | B19: 1 | C19: Law firm | D19: City of London | E19: Mills & Reeve LLP | F19: Mills & Reeve | G19: https://www.mills-reeve.com | H19: info@mills-reeve.com | I19: general | J19: Open page | K19: OC326165 | L19: Open | M19: Group | N19: 39133 | O19: 24 King William Street, London | P19: EC4R 9AT | Q19: No | W19: City of London School (EC4V 3AL) | X19: 14 | Y19: Marlborough Sports Garden (SE1 1SD) (14.5) | Z19: City of London School (EC4V 3AL) | AA19: 14 | AB19: =IFERROR(INDEX(Venues!$E$2:$E$17,MATCH(Z19,Venues!$A$2:$A$17,0)),"Not checked") | AC19: =IFERROR(INDEX(Venues!$F$2:$F$17,MATCH(Z19,Venues!$A$2:$A$17,0)),0) | AD19: =IFERROR(INDEX(Venues!$M$2:$M$17,MATCH(Z19,Venues!$A$2:$A$17,0)),"") | AE19: =IFERROR(INDEX(Venues!$N$2:$N$17,MATCH(Z19,Venues!$A$2:$A$17,0)),"5-a-side") | AF19: =IF(Offer!$C$4="","",Offer!$C$4) | AG19: =Z19&" ("&AA19&" min walk) · "&IF(ISNUMBER(AD19),TEXT(AD19,"ddd d mmm, hh:mm"),"slot to confirm with venue")&" · "&AE19&" · "&IF(AF19<>"","£"&TEXT(AF19,"0.00")&" pp","price TBC") | AH19: =IF(U19<>"",U19,IF(H19<>"",H19,"")) | AI19: ="After-work football for "&F19&" · "&Z19&", "&AA19&" min from your office" | AJ19: ="Hi "&IF(R19<>"",R19,F19&" team")&","&CHAR(10)&CHAR(10)&"I'm "&IF(AM19<>"",AM19,IF(Offer!$C$5<>"",Offer!$C$5,"[NAME]"))&" from FC Urban. We organise after-work football for teams in the City and Canary Wharf."&CHAR(10)&CHAR(10)&"We have a "&AE19&" pitch at "&Z19&", "&IF(OR(AA19=8,AA19=11,AA19=18),"an ","a ")&AA19&"-minute walk from your "&P19&" office, "&IF(ISNUMBER(AD19),"on "&TEXT(AD19,"dddd d mmmm")&" at "&TEXT(AD19,"hh:mm"),"on a weekday evening that suits your team")&". It's "&IF(AF19<>"","£"&IF(AF19=INT(AF19),TEXT(AF19,"0"),TEXT(AF19,"0.00")),"[PRICE PER PLAYER]")&" a player and we handle the pitch booking, sign-ups and payments, so all it takes is one person sharing a link with the team."&CHAR(10)&CHAR(10)&"It works well as a team social or "&IF(ISNUMBER(SEARCH(LEFT(F19,1),"AEIOU")),"an ","a ")&F19&" vs clients game. Would your team be up for it, or is there someone who'd enjoy organising it?"&IF(Offer!$C$7<>""," Spots are held until "&TEXT(Offer!$C$7,"dddd d mmmm")&".","")&" "&IF(Offer!$C$6<>"",Offer!$C$6,"[JOINING LINK]")&CHAR(10)&CHAR(10)&"Best,"&CHAR(10)&IF(AM19<>"",AM19,IF(Offer!$C$5<>"",Offer!$C$5,"[NAME]"))&CHAR(10)&"FC Urban" | AK19: ="Hi "&IF(R19<>"",R19,F19&" team")&","&CHAR(10)&CHAR(10)&"Just bumping this up. The "&AE19&" pitch at "&Z19&" is still free "&IF(ISNUMBER(AD19),TEXT(AD19,"ddd d mmm")&", "&TEXT(AD19,"hh:mm"),"weekday evenings")&", "&IF(OR(AA19=8,AA19=11,AA19=18),"an ","a ")&AA19&"-minute walk from your office, "&IF(AF19<>"","£"&IF(AF19=INT(AF19),TEXT(AF19,"0"),TEXT(AF19,"0.00")),"[PRICE PER PLAYER]")&" a player. Happy to hold it for "&F19&" if someone on the team fancies organising a game."&IF(Offer!$C$7<>""," Spots are held until "&TEXT(Offer!$C$7,"dddd d mmmm")&".","")&" "&IF(Offer!$C$6<>"",Offer!$C$6,"[JOINING LINK]")&CHAR(10)&CHAR(10)&"Best,"&CHAR(10)&IF(AM19<>"",AM19,IF(Offer!$C$5<>"",Offer!$C$5,"[NAME]"))&CHAR(10)&"FC Urban" | AL19: =IF(AH19="","No email yet",IF(ISNUMBER(SEARCH("[",AJ19)),"Fill placeholders",IF(ISNUMBER(AD19),"Ready to send","Ready · no fixed slot")))
A20: 18 | B20: 1 | C20: Law firm | D20: City of London | E20: DLA Piper International LLP | F20: DLA Piper | G20: https://www.dlapiper.com | H20: communications@dlapiper.com | I20: role (press / marketing) | J20: Open page | K20: OC305357 | L20: Open | M20: Group | N20: 37855 | O20: 160 Aldersgate Street, London | P20: EC1A 4HT | Q20: No | W20: Finsbury Leisure Centre (EC1V 3PU) | X20: 14 | Y20: City of London School (EC4V 3AL) (14); Old St - Moreland Primary School (18.4) | Z20: City of London School (EC4V 3AL) | AA20: 14 | AB20: =IFERROR(INDEX(Venues!$E$2:$E$17,MATCH(Z20,Venues!$A$2:$A$17,0)),"Not checked") | AC20: =IFERROR(INDEX(Venues!$F$2:$F$17,MATCH(Z20,Venues!$A$2:$A$17,0)),0) | AD20: =IFERROR(INDEX(Venues!$M$2:$M$17,MATCH(Z20,Venues!$A$2:$A$17,0)),"") | AE20: =IFERROR(INDEX(Venues!$N$2:$N$17,MATCH(Z20,Venues!$A$2:$A$17,0)),"5-a-side") | AF20: =IF(Offer!$C$4="","",Offer!$C$4) | AG20: =Z20&" ("&AA20&" min walk) · "&IF(ISNUMBER(AD20),TEXT(AD20,"ddd d mmm, hh:mm"),"slot to confirm with venue")&" · "&AE20&" · "&IF(AF20<>"","£"&TEXT(AF20,"0.00")&" pp","price TBC") | AH20: =IF(U20<>"",U20,IF(H20<>"",H20,"")) | AI20: ="After-work football for "&F20&" · "&Z20&", "&AA20&" min from your office" | AJ20: ="Hi "&IF(R20<>"",R20,F20&" team")&","&CHAR(10)&CHAR(10)&"I'm "&IF(AM20<>"",AM20,IF(Offer!$C$5<>"",Offer!$C$5,"[NAME]"))&" from FC Urban. We organise after-work football for teams in the City and Canary Wharf."&CHAR(10)&CHAR(10)&"We have a "&AE20&" pitch at "&Z20&", "&IF(OR(AA20=8,AA20=11,AA20=18),"an ","a ")&AA20&"-minute walk from your "&P20&" office, "&IF(ISNUMBER(AD20),"on "&TEXT(AD20,"dddd d mmmm")&" at "&TEXT(AD20,"hh:mm"),"on a weekday evening that suits your team")&". It's "&IF(AF20<>"","£"&IF(AF20=INT(AF20),TEXT(AF20,"0"),TEXT(AF20,"0.00")),"[PRICE PER PLAYER]")&" a player and we handle the pitch booking, sign-ups and payments, so all it takes is one person sharing a link with the team."&CHAR(10)&CHAR(10)&"It works well as a team social or "&IF(ISNUMBER(SEARCH(LEFT(F20,1),"AEIOU")),"an ","a ")&F20&" vs clients game. Would your team be up for it, or is there someone who'd enjoy organising it?"&IF(Offer!$C$7<>""," Spots are held until "&TEXT(Offer!$C$7,"dddd d mmmm")&".","")&" "&IF(Offer!$C$6<>"",Offer!$C$6,"[JOINING LINK]")&CHAR(10)&CHAR(10)&"Best,"&CHAR(10)&IF(AM20<>"",AM20,IF(Offer!$C$5<>"",Offer!$C$5,"[NAME]"))&CHAR(10)&"FC Urban" | AK20: ="Hi "&IF(R20<>"",R20,F20&" team")&","&CHAR(10)&CHAR(10)&"Just bumping this up. The "&AE20&" pitch at "&Z20&" is still free "&IF(ISNUMBER(AD20),TEXT(AD20,"ddd d mmm")&", "&TEXT(AD20,"hh:mm"),"weekday evenings")&", "&IF(OR(AA20=8,AA20=11,AA20=18),"an ","a ")&AA20&"-minute walk from your office, "&IF(AF20<>"","£"&IF(AF20=INT(AF20),TEXT(AF20,"0"),TEXT(AF20,"0.00")),"[PRICE PER PLAYER]")&" a player. Happy to hold it for "&F20&" if someone on the team fancies organising a game."&IF(Offer!$C$7<>""," Spots are held until "&TEXT(Offer!$C$7,"dddd d mmmm")&".","")&" "&IF(Offer!$C$6<>"",Offer!$C$6,"[JOINING LINK]")&CHAR(10)&CHAR(10)&"Best,"&CHAR(10)&IF(AM20<>"",AM20,IF(Offer!$C$5<>"",Offer!$C$5,"[NAME]"))&CHAR(10)&"FC Urban" | AL20: =IF(AH20="","No email yet",IF(ISNUMBER(SEARCH("[",AJ20)),"Fill placeholders",IF(ISNUMBER(AD20),"Ready to send","Ready · no fixed slot")))
