Workbook

Sheet Outreach
A1: Lead | M1: Tagged venue | R1: Fallback pitch | W1: Lead with (message) | AB1: Tracking — fill in
A2: # | B2: Tier | C2: Segment | D2: List | E2: Business | F2: Industry | G2: Email | H2: Email type | I2: Phone | J2: Website | K2: Address | L2: Postcode | M2: Tagged venue | N2: Walk (min) | O2: Status | P2: Open slots | Q2: Earliest slot | R2: Bookable nearby? | S2: Fallback venue | T2: Fallback slot | U2: Format | V2: Cost per player at cost (£) | W2: Lead with: venue | X2: Lead with: slot | Y2: Lead with: format | Z2: Lead with: price per player (£) | AA2: Lead-with line (for drafting) | AB2: Owner | AC2: Channel | AD2: Contacted on | AE2: Replied | AF2: Call booked | AG2: Group created | AH2: First game booked | AI2: Second game booked | AJ2: Sees us as competitor? | AK2: Objection (exact words) | AL2: Next step | AM2: Notes
A3: 1 | B3: 1 · E2 Haggerston | C3: Hospitality | D3: Local businesses | E3: E. Pellicci | F3: amenity: cafe | G3: epelliccicafe@gmail.com | H3: openstreetmap_tag | I3: +44 20 7739 4873 | J3: https://epellicci.co.uk/ | K3: Bethnal Green Road 332, London | L3: E2 0AG | M3: Stepney 3G | N3: 18 | O3: =IFERROR(INDEX(Venues!$C$2:$C$10,MATCH(M3,Venues!$A$2:$A$10,0)),"Not checked") | P3: =IFERROR(INDEX(Venues!$D$2:$D$10,MATCH(M3,Venues!$A$2:$A$10,0)),0) | Q3: =IFERROR(INDEX(Venues!$E$2:$E$10,MATCH(M3,Venues!$A$2:$A$10,0)),"") | R3: =IF(P3>0,"Yes","No") | S3: COLA Shoreditch Park | T3: =IFERROR(INDEX(Venues!$E$2:$E$10,MATCH(S3,Venues!$A$2:$A$10,0)),"") | U3: =IFERROR(INDEX(Venues!$F$2:$F$10,MATCH(S3,Venues!$A$2:$A$10,0)),"") | V3: =IFERROR(INDEX(Venues!$H$2:$H$10,MATCH(S3,Venues!$A$2:$A$10,0)),"") | W3: =IF('Pilot offer'!$C$24="Yes",'Pilot offer'!$C$3,S3) | X3: =IF('Pilot offer'!$C$24="Yes",'Pilot offer'!$C$5+'Pilot offer'!$C$6,T3) | Y3: =IF('Pilot offer'!$C$24="Yes",'Pilot offer'!$C$8,U3) | Z3: =IF('Pilot offer'!$C$24="Yes",'Pilot offer'!$C$11,"") | AA3: =IF(X3="","",W3&" · "&TEXT(X3,"ddd d mmm, hh:mm")&" · "&Y3&IF(Z3<>""," · £"&TEXT(Z3,"0.00")&" per player"," · price TBC (cost £"&TEXT(V3,"0.00")&" pp)"))
A4: 2 | B4: 1 · E2 Haggerston | C4: Retail | D4: Local businesses | E4: Trotters Jewellers | F4: shop: jewelry | G4: info@trottersjewellers.com | H4: general | I4: +44 7399 606868 | J4: http://www.trottersjewellers.com/ | K4: Bethnal Green Road 350, London | L4: E2 0AH | M4: Stepney 3G | N4: 17 | O4: =IFERROR(INDEX(Venues!$C$2:$C$10,MATCH(M4,Venues!$A$2:$A$10,0)),"Not checked") | P4: =IFERROR(INDEX(Venues!$D$2:$D$10,MATCH(M4,Venues!$A$2:$A$10,0)),0) | Q4: =IFERROR(INDEX(Venues!$E$2:$E$10,MATCH(M4,Venues!$A$2:$A$10,0)),"") | R4: =IF(P4>0,"Yes","No") | S4: COLA Shoreditch Park | T4: =IFERROR(INDEX(Venues!$E$2:$E$10,MATCH(S4,Venues!$A$2:$A$10,0)),"") | U4: =IFERROR(INDEX(Venues!$F$2:$F$10,MATCH(S4,Venues!$A$2:$A$10,0)),"") | V4: =IFERROR(INDEX(Venues!$H$2:$H$10,MATCH(S4,Venues!$A$2:$A$10,0)),"") | W4: =IF('Pilot offer'!$C$24="Yes",'Pilot offer'!$C$3,S4) | X4: =IF('Pilot offer'!$C$24="Yes",'Pilot offer'!$C$5+'Pilot offer'!$C$6,T4) | Y4: =IF('Pilot offer'!$C$24="Yes",'Pilot offer'!$C$8,U4) | Z4: =IF('Pilot offer'!$C$24="Yes",'Pilot offer'!$C$11,"") | AA4: =IF(X4="","",W4&" · "&TEXT(X4,"ddd d mmm, hh:mm")&" · "&Y4&IF(Z4<>""," · £"&TEXT(Z4,"0.00")&" per player"," · price TBC (cost £"&TEXT(V4,"0.00")&" pp)"))
A5: 3 | B5: 1 · E2 Haggerston | C5: Hospitality | D5: Local businesses | E5: The Old George | F5: amenity: pub | G5: oldgeorge@anticlondon.com | H5: openstreetmap_tag | I5: +44 20 7033 9726 | J5: https://www.crafted-social.co.uk/old-george-bethnal-green | K5: Bethnal Green Road 379, London | L5: E2 0AN | M5: Stepney 3G | N5: 15 | O5: =IFERROR(INDEX(Venues!$C$2:$C$10,MATCH(M5,Venues!$A$2:$A$10,0)),"Not checked") | P5: =IFERROR(INDEX(Venues!$D$2:$D$10,MATCH(M5,Venues!$A$2:$A$10,0)),0) | Q5: =IFERROR(INDEX(Venues!$E$2:$E$10,MATCH(M5,Venues!$A$2:$A$10,0)),"") | R5: =IF(P5>0,"Yes","No") | S5: COLA Shoreditch Park | T5: =IFERROR(INDEX(Venues!$E$2:$E$10,MATCH(S5,Venues!$A$2:$A$10,0)),"") | U5: =IFERROR(INDEX(Venues!$F$2:$F$10,MATCH(S5,Venues!$A$2:$A$10,0)),"") | V5: =IFERROR(INDEX(Venues!$H$2:$H$10,MATCH(S5,Venues!$A$2:$A$10,0)),"") | W5: =IF('Pilot offer'!$C$24="Yes",'Pilot offer'!$C$3,S5) | X5: =IF('Pilot offer'!$C$24="Yes",'Pilot offer'!$C$5+'Pilot offer'!$C$6,T5) | Y5: =IF('Pilot offer'!$C$24="Yes",'Pilot offer'!$C$8,U5) | Z5: =IF('Pilot offer'!$C$24="Yes",'Pilot offer'!$C$11,"") | AA5: =IF(X5="","",W5&" · "&TEXT(X5,"ddd d mmm, hh:mm")&" · "&Y5&IF(Z5<>""," · £"&TEXT(Z5,"0.00")&" per player"," · price TBC (cost £"&TEXT(V5,"0.00")&" pp)"))
A6: 4 | B6: 1 · E2 Haggerston | C6: Hospitality | D6: Local businesses | E6: The Sun Tavern | F6: amenity: pub | G6: info@thesuntavern.co.uk | H6: general | J6: https://www.thesuntavern.co.uk/ | K6: Bethnal Green Road 441, London | L6: E2 0AN | M6: Stepney 3G | N6: 13 | O6: =IFERROR(INDEX(Venues!$C$2:$C$10,MATCH(M6,Venues!$A$2:$A$10,0)),"Not checked") | P6: =IFERROR(INDEX(Venues!$D$2:$D$10,MATCH(M6,Venues!$A$2:$A$10,0)),0) | Q6: =IFERROR(INDEX(Venues!$E$2:$E$10,MATCH(M6,Venues!$A$2:$A$10,0)),"") | R6: =IF(P6>0,"Yes","No") | S6: COLA Shoreditch Park | T6: =IFERROR(INDEX(Venues!$E$2:$E$10,MATCH(S6,Venues!$A$2:$A$10,0)),"") | U6: =IFERROR(INDEX(Venues!$F$2:$F$10,MATCH(S6,Venues!$A$2:$A$10,0)),"") | V6: =IFERROR(INDEX(Venues!$H$2:$H$10,MATCH(S6,Venues!$A$2:$A$10,0)),"") | W6: =IF('Pilot offer'!$C$24="Yes",'Pilot offer'!$C$3,S6) | X6: =IF('Pilot offer'!$C$24="Yes",'Pilot offer'!$C$5+'Pilot offer'!$C$6,T6) | Y6: =IF('Pilot offer'!$C$24="Yes",'Pilot offer'!$C$8,U6) | Z6: =IF('Pilot offer'!$C$24="Yes",'Pilot offer'!$C$11,"") | AA6: =IF(X6="","",W6&" · "&TEXT(X6,"ddd d mmm, hh:mm")&" · "&Y6&IF(Z6<>""," · £"&TEXT(Z6,"0.00")&" per player"," · price TBC (cost £"&TEXT(V6,"0.00")&" pp)"))
A7: 5 | B7: 1 · E2 Haggerston | C7: Hospitality | D7: Local businesses | E7: Hostelle | F7: tourism: hostel | G7: info@hostelle.co.uk | H7: general | I7: +44 20 7646 6671 | J7: https://www.hostelle.co.uk/ | K7: Bethnal Green Road 458, London | L7: E2 0EA | M7: Stepney 3G | N7: 12 | O7: =IFERROR(INDEX(Venues!$C$2:$C$10,MATCH(M7,Venues!$A$2:$A$10,0)),"Not checked") | P7: =IFERROR(INDEX(Venues!$D$2:$D$10,MATCH(M7,Venues!$A$2:$A$10,0)),0) | Q7: =IFERROR(INDEX(Venues!$E$2:$E$10,MATCH(M7,Venues!$A$2:$A$10,0)),"") | R7: =IF(P7>0,"Yes","No") | S7: COLA Shoreditch Park | T7: =IFERROR(INDEX(Venues!$E$2:$E$10,MATCH(S7,Venues!$A$2:$A$10,0)),"") | U7: =IFERROR(INDEX(Venues!$F$2:$F$10,MATCH(S7,Venues!$A$2:$A$10,0)),"") | V7: =IFERROR(INDEX(Venues!$H$2:$H$10,MATCH(S7,Venues!$A$2:$A$10,0)),"") | W7: =IF('Pilot offer'!$C$24="Yes",'Pilot offer'!$C$3,S7) | X7: =IF('Pilot offer'!$C$24="Yes",'Pilot offer'!$C$5+'Pilot offer'!$C$6,T7) | Y7: =IF('Pilot offer'!$C$24="Yes",'Pilot offer'!$C$8,U7) | Z7: =IF('Pilot offer'!$C$24="Yes",'Pilot offer'!$C$11,"") | AA7: =IF(X7="","",W7&" · "&TEXT(X7,"ddd d mmm, hh:mm")&" · "&Y7&IF(Z7<>""," · £"&TEXT(Z7,"0.00")&" per player"," · price TBC (cost £"&TEXT(V7,"0.00")&" pp)"))
A8: 6 | B8: 1 · E2 Haggerston | C8: Leisure & culture | D8: Local businesses | E8: Backyard Comedy Club | F8: amenity: theatre | G8: info@backyardcomedyclub.co.uk | H8: general | J8: https://backyardcomedyclub.co.uk/ | K8: Cambridge Heath Road 231, London | L8: E2 0EL | M8: Stepney 3G | N8: 9 | O8: =IFERROR(INDEX(Venues!$C$2:$C$10,MATCH(M8,Venues!$A$2:$A$10,0)),"Not checked") | P8: =IFERROR(INDEX(Venues!$D$2:$D$10,MATCH(M8,Venues!$A$2:$A$10,0)),0) | Q8: =IFERROR(INDEX(Venues!$E$2:$E$10,MATCH(M8,Venues!$A$2:$A$10,0)),"") | R8: =IF(P8>0,"Yes","No") | S8: COLA Shoreditch Park | T8: =IFERROR(INDEX(Venues!$E$2:$E$10,MATCH(S8,Venues!$A$2:$A$10,0)),"") | U8: =IFERROR(INDEX(Venues!$F$2:$F$10,MATCH(S8,Venues!$A$2:$A$10,0)),"") | V8: =IFERROR(INDEX(Venues!$H$2:$H$10,MATCH(S8,Venues!$A$2:$A$10,0)),"") | W8: =IF('Pilot offer'!$C$24="Yes",'Pilot offer'!$C$3,S8) | X8: =IF('Pilot offer'!$C$24="Yes",'Pilot offer'!$C$5+'Pilot offer'!$C$6,T8) | Y8: =IF('Pilot offer'!$C$24="Yes",'Pilot offer'!$C$8,U8) | Z8: =IF('Pilot offer'!$C$24="Yes",'Pilot offer'!$C$11,"") | AA8: =IF(X8="","",W8&" · "&TEXT(X8,"ddd d mmm, hh:mm")&" · "&Y8&IF(Z8<>""," · £"&TEXT(Z8,"0.00")&" per player"," · price TBC (cost £"&TEXT(V8,"0.00")&" pp)"))
A9: 7 | B9: 1 · E2 Haggerston | C9: Hospitality | D9: Local businesses | E9: Three Colts Tavern | F9: amenity: pub | G9: info@threecoltstavern.co.uk | H9: general | J9: https://www.threecoltstavern.co.uk/ | K9: Cambridge Heath Road 199, London | L9: E2 0EL | M9: Stepney 3G | N9: 8 | O9: =IFERROR(INDEX(Venues!$C$2:$C$10,MATCH(M9,Venues!$A$2:$A$10,0)),"Not checked") | P9: =IFERROR(INDEX(Venues!$D$2:$D$10,MATCH(M9,Venues!$A$2:$A$10,0)),0) | Q9: =IFERROR(INDEX(Venues!$E$2:$E$10,MATCH(M9,Venues!$A$2:$A$10,0)),"") | R9: =IF(P9>0,"Yes","No") | S9: COLA Shoreditch Park | T9: =IFERROR(INDEX(Venues!$E$2:$E$10,MATCH(S9,Venues!$A$2:$A$10,0)),"") | U9: =IFERROR(INDEX(Venues!$F$2:$F$10,MATCH(S9,Venues!$A$2:$A$10,0)),"") | V9: =IFERROR(INDEX(Venues!$H$2:$H$10,MATCH(S9,Venues!$A$2:$A$10,0)),"") | W9: =IF('Pilot offer'!$C$24="Yes",'Pilot offer'!$C$3,S9) | X9: =IF('Pilot offer'!$C$24="Yes",'Pilot offer'!$C$5+'Pilot offer'!$C$6,T9) | Y9: =IF('Pilot offer'!$C$24="Yes",'Pilot offer'!$C$8,U9) | Z9: =IF('Pilot offer'!$C$24="Yes",'Pilot offer'!$C$11,"") | AA9: =IF(X9="","",W9&" · "&TEXT(X9,"ddd d mmm, hh:mm")&" · "&Y9&IF(Z9<>""," · £"&TEXT(Z9,"0.00")&" per player"," · price TBC (cost £"&TEXT(V9,"0.00")&" pp)"))
A10: 8 | B10: 1 · E2 Haggerston | C10: Education | D10: Local businesses | E10: Darul Hadis Latifiah | F10: amenity: school | G10: info@darulhadis.org.uk | H10: general | I10: +44 20 8983 3663 | J10: https://www.darulhadis.org.uk/ | K10: Cornwall Avenue 1, London | L10: E2 0HW | M10: Stepney 3G | N10: 8 | O10: =IFERROR(INDEX(Venues!$C$2:$C$10,MATCH(M10,Venues!$A$2:$A$10,0)),"Not checked") | P10: =IFERROR(INDEX(Venues!$D$2:$D$10,MATCH(M10,Venues!$A$2:$A$10,0)),0) | Q10: =IFERROR(INDEX(Venues!$E$2:$E$10,MATCH(M10,Venues!$A$2:$A$10,0)),"") | R10: =IF(P10>0,"Yes","No") | S10: COLA Shoreditch Park | T10: =IFERROR(INDEX(Venues!$E$2:$E$10,MATCH(S10,Venues!$A$2:$A$10,0)),"") | U10: =IFERROR(INDEX(Venues!$F$2:$F$10,MATCH(S10,Venues!$A$2:$A$10,0)),"") | V10: =IFERROR(INDEX(Venues!$H$2:$H$10,MATCH(S10,Venues!$A$2:$A$10,0)),"") | W10: =IF('Pilot offer'!$C$24="Yes",'Pilot offer'!$C$3,S10) | X10: =IF('Pilot offer'!$C$24="Yes",'Pilot offer'!$C$5+'Pilot offer'!$C$6,T10) | Y10: =IF('Pilot offer'!$C$24="Yes",'Pilot offer'!$C$8,U10) | Z10: =IF('Pilot offer'!$C$24="Yes",'Pilot offer'!$C$11,"") | AA10: =IF(X10="","",W10&" · "&TEXT(X10,"ddd d mmm, hh:mm")&" · "&Y10&IF(Z10<>""," · £"&TEXT(Z10,"0.00")&" per player"," · price TBC (cost £"&TEXT(V10,"0.00")&" pp)"))
A11: 9 | B11: 1 · E2 Haggerston | C11: Retail | D11: Local businesses | E11: Quality Dry Cleaners | F11: shop: dry cleaning | G11: info@qualitydrycleaners.org.uk | H11: openstreetmap_tag | I11: +44 20 8983 4502 | J11: https://qualitydrycleaners.org.uk/ | K11: Globe Road 262, London | L11: E2 0JD | M11: Stepney 3G | N11: 9 | O11: =IFERROR(INDEX(Venues!$C$2:$C$10,MATCH(M11,Venues!$A$2:$A$10,0)),"Not checked") | P11: =IFERROR(INDEX(Venues!$D$2:$D$10,MATCH(M11,Venues!$A$2:$A$10,0)),0) | Q11: =IFERROR(INDEX(Venues!$E$2:$E$10,MATCH(M11,Venues!$A$2:$A$10,0)),"") | R11: =IF(P11>0,"Yes","No") | S11: COLA Shoreditch Park | T11: =IFERROR(INDEX(Venues!$E$2:$E$10,MATCH(S11,Venues!$A$2:$A$10,0)),"") | U11: =IFERROR(INDEX(Venues!$F$2:$F$10,MATCH(S11,Venues!$A$2:$A$10,0)),"") | V11: =IFERROR(INDEX(Venues!$H$2:$H$10,MATCH(S11,Venues!$A$2:$A$10,0)),"") | W11: =IF('Pilot offer'!$C$24="Yes",'Pilot offer'!$C$3,S11) | X11: =IF('Pilot offer'!$C$24="Yes",'Pilot offer'!$C$5+'Pilot offer'!$C$6,T11) | Y11: =IF('Pilot offer'!$C$24="Yes",'Pilot offer'!$C$8,U11) | Z11: =IF('Pilot offer'!$C$24="Yes",'Pilot offer'!$C$11,"") | AA11: =IF(X11="","",W11&" · "&TEXT(X11,"ddd d mmm, hh:mm")&" · "&Y11&IF(Z11<>""," · £"&TEXT(Z11,"0.00")&" per player"," · price TBC (cost £"&TEXT(V11,"0.00")&" pp)"))
A12: 10 | B12: 1 · E2 Haggerston | C12: Education | D12: Local businesses | E12: Bangabandhu Primary School | F12: amenity: school | G12: admin@bangabandhu.towerhamlets.sch.uk | H12: general | I12: +44 20 8980 0580 | J12: https://www.bangabandhu.towerhamlets.sch.uk/ | K12: Wessex Street 28, London | L12: E2 0LB | M12: Stepney 3G | N12: 6 | O12: =IFERROR(INDEX(Venues!$C$2:$C$10,MATCH(M12,Venues!$A$2:$A$10,0)),"Not checked") | P12: =IFERROR(INDEX(Venues!$D$2:$D$10,MATCH(M12,Venues!$A$2:$A$10,0)),0) | Q12: =IFERROR(INDEX(Venues!$E$2:$E$10,MATCH(M12,Venues!$A$2:$A$10,0)),"") | R12: =IF(P12>0,"Yes","No") | S12: COLA Shoreditch Park | T12: =IFERROR(INDEX(Venues!$E$2:$E$10,MATCH(S12,Venues!$A$2:$A$10,0)),"") | U12: =IFERROR(INDEX(Venues!$F$2:$F$10,MATCH(S12,Venues!$A$2:$A$10,0)),"") | V12: =IFERROR(INDEX(Venues!$H$2:$H$10,MATCH(S12,Venues!$A$2:$A$10,0)),"") | W12: =IF('Pilot offer'!$C$24="Yes",'Pilot offer'!$C$3,S12) | X12: =IF('Pilot offer'!$C$24="Yes",'Pilot offer'!$C$5+'Pilot offer'!$C$6,T12) | Y12: =IF('Pilot offer'!$C$24="Yes",'Pilot offer'!$C$8,U12) | Z12: =IF('Pilot offer'!$C$24="Yes",'Pilot offer'!$C$11,"") | AA12: =IF(X12="","",W12&" · "&TEXT(X12,"ddd d mmm, hh:mm")&" · "&Y12&IF(Z12<>""," · £"&TEXT(Z12,"0.00")&" per player"," · price TBC (cost £"&TEXT(V12,"0.00")&" pp)"))
A13: 11 | B13: 1 · E2 Haggerston | C13: Education | D13: Local businesses | E13: Bonner Primary School | F13: amenity: school | G13: admin@bonner.towerhamlets.sch.uk | H13: general | I13: +44 20 8980 1004 | J13: https://www.bonner.towerhamlets.sch.uk/ | K13: Stainsbury Street, London | L13: E2 0NF | M13: Stepney 3G | N13: 9 | O13: =IFERROR(INDEX(Venues!$C$2:$C$10,MATCH(M13,Venues!$A$2:$A$10,0)),"Not checked") | P13: =IFERROR(INDEX(Venues!$D$2:$D$10,MATCH(M13,Venues!$A$2:$A$10,0)),0) | Q13: =IFERROR(INDEX(Venues!$E$2:$E$10,MATCH(M13,Venues!$A$2:$A$10,0)),"") | R13: =IF(P13>0,"Yes","No") | S13: COLA Shoreditch Park | T13: =IFERROR(INDEX(Venues!$E$2:$E$10,MATCH(S13,Venues!$A$2:$A$10,0)),"") | U13: =IFERROR(INDEX(Venues!$F$2:$F$10,MATCH(S13,Venues!$A$2:$A$10,0)),"") | V13: =IFERROR(INDEX(Venues!$H$2:$H$10,MATCH(S13,Venues!$A$2:$A$10,0)),"") | W13: =IF('Pilot offer'!$C$24="Yes",'Pilot offer'!$C$3,S13) | X13: =IF('Pilot offer'!$C$24="Yes",'Pilot offer'!$C$5+'Pilot offer'!$C$6,T13) | Y13: =IF('Pilot offer'!$C$24="Yes",'Pilot offer'!$C$8,U13) | Z13: =IF('Pilot offer'!$C$24="Yes",'Pilot offer'!$C$11,"") | AA13: =IF(X13="","",W13&" · "&TEXT(X13,"ddd d mmm, hh:mm")&" · "&Y13&IF(Z13<>""," · £"&TEXT(Z13,"0.00")&" per player"," · price TBC (cost £"&TEXT(V13,"0.00")&" pp)"))
A14: 12 | B14: 1 · E2 Haggerston | C14: Office & professional | D14: Corporate | E14: BRS CONSULTING LTD | F14: finance | G14: info@brsconsulting.co.uk | H14: general | I14: +44 7979 781072 | J14: https://www.brsconsulting.co.uk/ | K14: 125 Roman Rd, Globe Town, London E2 0QN, UK | L14: E2 0QN | M14: Stepney 3G | N14: 9 | O14: =IFERROR(INDEX(Venues!$C$2:$C$10,MATCH(M14,Venues!$A$2:$A$10,0)),"Not checked") | P14: =IFERROR(INDEX(Venues!$D$2:$D$10,MATCH(M14,Venues!$A$2:$A$10,0)),0) | Q14: =IFERROR(INDEX(Venues!$E$2:$E$10,MATCH(M14,Venues!$A$2:$A$10,0)),"") | R14: =IF(P14>0,"Yes","No") | S14: COLA Shoreditch Park | T14: =IFERROR(INDEX(Venues!$E$2:$E$10,MATCH(S14,Venues!$A$2:$A$10,0)),"") | U14: =IFERROR(INDEX(Venues!$F$2:$F$10,MATCH(S14,Venues!$A$2:$A$10,0)),"") | V14: =IFERROR(INDEX(Venues!$H$2:$H$10,MATCH(S14,Venues!$A$2:$A$10,0)),"") | W14: =IF('Pilot offer'!$C$24="Yes",'Pilot offer'!$C$3,S14) | X14: =IF('Pilot offer'!$C$24="Yes",'Pilot offer'!$C$5+'Pilot offer'!$C$6,T14) | Y14: =IF('Pilot offer'!$C$24="Yes",'Pilot offer'!$C$8,U14) | Z14: =IF('Pilot offer'!$C$24="Yes",'Pilot offer'!$C$11,"") | AA14: =IF(X14="","",W14&" · "&TEXT(X14,"ddd d mmm, hh:mm")&" · "&Y14&IF(Z14<>""," · £"&TEXT(Z14,"0.00")&" per player"," · price TBC (cost £"&TEXT(V14,"0.00")&" pp)"))
A15: 13 | B15: 1 · E2 Haggerston | C15: Leisure & culture | D15: Local businesses | E15: Four Corners | F15: tourism: gallery | G15: info@fourcornersfilm.co.uk | H15: general | I15: +44 20 8981 6111 | J15: https://www.fourcornersfilm.co.uk/ | K15: Roman Road 121, London | L15: E2 0QN | M15: Stepney 3G | N15: 9 | O15: =IFERROR(INDEX(Venues!$C$2:$C$10,MATCH(M15,Venues!$A$2:$A$10,0)),"Not checked") | P15: =IFERROR(INDEX(Venues!$D$2:$D$10,MATCH(M15,Venues!$A$2:$A$10,0)),0) | Q15: =IFERROR(INDEX(Venues!$E$2:$E$10,MATCH(M15,Venues!$A$2:$A$10,0)),"") | R15: =IF(P15>0,"Yes","No") | S15: COLA Shoreditch Park | T15: =IFERROR(INDEX(Venues!$E$2:$E$10,MATCH(S15,Venues!$A$2:$A$10,0)),"") | U15: =IFERROR(INDEX(Venues!$F$2:$F$10,MATCH(S15,Venues!$A$2:$A$10,0)),"") | V15: =IFERROR(INDEX(Venues!$H$2:$H$10,MATCH(S15,Venues!$A$2:$A$10,0)),"") | W15: =IF('Pilot offer'!$C$24="Yes",'Pilot offer'!$C$3,S15) | X15: =IF('Pilot offer'!$C$24="Yes",'Pilot offer'!$C$5+'Pilot offer'!$C$6,T15) | Y15: =IF('Pilot offer'!$C$24="Yes",'Pilot offer'!$C$8,U15) | Z15: =IF('Pilot offer'!$C$24="Yes",'Pilot offer'!$C$11,"") | AA15: =IF(X15="","",W15&" · "&TEXT(X15,"ddd d mmm, hh:mm")&" · "&Y15&IF(Z15<>""," · £"&TEXT(Z15,"0.00")&" per player"," · price TBC (cost £"&TEXT(V15,"0.00")&" pp)"))
A16: 14 | B16: 1 · E2 Haggerston | C16: Retail | D16: Local businesses | E16: Paradise Cycles | F16: shop: bicycle | G16: info@paradisecycles.co.uk | H16: general | I16: +44 20 3441 9220 | J16: https://www.paradisecycles.co.uk/ | K16: Roman Road 63, London | L16: E2 0QN | M16: Stepney 3G | N16: 8 | O16: =IFERROR(INDEX(Venues!$C$2:$C$10,MATCH(M16,Venues!$A$2:$A$10,0)),"Not checked") | P16: =IFERROR(INDEX(Venues!$D$2:$D$10,MATCH(M16,Venues!$A$2:$A$10,0)),0) | Q16: =IFERROR(INDEX(Venues!$E$2:$E$10,MATCH(M16,Venues!$A$2:$A$10,0)),"") | R16: =IF(P16>0,"Yes","No") | S16: COLA Shoreditch Park | T16: =IFERROR(INDEX(Venues!$E$2:$E$10,MATCH(S16,Venues!$A$2:$A$10,0)),"") | U16: =IFERROR(INDEX(Venues!$F$2:$F$10,MATCH(S16,Venues!$A$2:$A$10,0)),"") | V16: =IFERROR(INDEX(Venues!$H$2:$H$10,MATCH(S16,Venues!$A$2:$A$10,0)),"") | W16: =IF('Pilot offer'!$C$24="Yes",'Pilot offer'!$C$3,S16) | X16: =IF('Pilot offer'!$C$24="Yes",'Pilot offer'!$C$5+'Pilot offer'!$C$6,T16) | Y16: =IF('Pilot offer'!$C$24="Yes",'Pilot offer'!$C$8,U16) | Z16: =IF('Pilot offer'!$C$24="Yes",'Pilot offer'!$C$11,"") | AA16: =IF(X16="","",W16&" · "&TEXT(X16,"ddd d mmm, hh:mm")&" · "&Y16&IF(Z16<>""," · £"&TEXT(Z16,"0.00")&" per player"," · price TBC (cost £"&TEXT(V16,"0.00")&" pp)"))
A17: 15 | B17: 1 · E2 Haggerston | C17: Office & professional | D17: Corporate | E17: Hamletts.com | F17: estate_agent | G17: info@hamletts.com | H17: openstreetmap_tag | I17: +44 20 8980 3377 | K17: 236 Roman Road, London | L17: E2 0RY | M17: Stepney 3G | N17: 12 | O17: =IFERROR(INDEX(Venues!$C$2:$C$10,MATCH(M17,Venues!$A$2:$A$10,0)),"Not checked") | P17: =IFERROR(INDEX(Venues!$D$2:$D$10,MATCH(M17,Venues!$A$2:$A$10,0)),0) | Q17: =IFERROR(INDEX(Venues!$E$2:$E$10,MATCH(M17,Venues!$A$2:$A$10,0)),"") | R17: =IF(P17>0,"Yes","No") | S17: COLA Shoreditch Park | T17: =IFERROR(INDEX(Venues!$E$2:$E$10,MATCH(S17,Venues!$A$2:$A$10,0)),"") | U17: =IFERROR(INDEX(Venues!$F$2:$F$10,MATCH(S17,Venues!$A$2:$A$10,0)),"") | V17: =IFERROR(INDEX(Venues!$H$2:$H$10,MATCH(S17,Venues!$A$2:$A$10,0)),"") | W17: =IF('Pilot offer'!$C$24="Yes",'Pilot offer'!$C$3,S17) | X17: =IF('Pilot offer'!$C$24="Yes",'Pilot offer'!$C$5+'Pilot offer'!$C$6,T17) | Y17: =IF('Pilot offer'!$C$24="Yes",'Pilot offer'!$C$8,U17) | Z17: =IF('Pilot offer'!$C$24="Yes",'Pilot offer'!$C$11,"") | AA17: =IF(X17="","",W17&" · "&TEXT(X17,"ddd d mmm, hh:mm")&" · "&Y17&IF(Z17<>""," · £"&TEXT(Z17,"0.00")&" per player"," · price TBC (cost £"&TEXT(V17,"0.00")&" pp)"))
A18: 16 | B18: 1 · E2 Haggerston | C18: Office & professional | D18: Corporate | E18: Keystones Properties | F18: estate_agent | G18: info@keystonesltd.co.uk | H18: general | I18: +44 20 8981 9955 | J18: https://www.keystonesltd.co.uk/ | K18: 146 Roman Road, London | L18: E2 0RY | M18: Stepney 3G | N18: 9 | O18: =IFERROR(INDEX(Venues!$C$2:$C$10,MATCH(M18,Venues!$A$2:$A$10,0)),"Not checked") | P18: =IFERROR(INDEX(Venues!$D$2:$D$10,MATCH(M18,Venues!$A$2:$A$10,0)),0) | Q18: =IFERROR(INDEX(Venues!$E$2:$E$10,MATCH(M18,Venues!$A$2:$A$10,0)),"") | R18: =IF(P18>0,"Yes","No") | S18: COLA Shoreditch Park | T18: =IFERROR(INDEX(Venues!$E$2:$E$10,MATCH(S18,Venues!$A$2:$A$10,0)),"") | U18: =IFERROR(INDEX(Venues!$F$2:$F$10,MATCH(S18,Venues!$A$2:$A$10,0)),"") | V18: =IFERROR(INDEX(Venues!$H$2:$H$10,MATCH(S18,Venues!$A$2:$A$10,0)),"") | W18: =IF('Pilot offer'!$C$24="Yes",'Pilot offer'!$C$3,S18) | X18: =IF('Pilot offer'!$C$24="Yes",'Pilot offer'!$C$5+'Pilot offer'!$C$6,T18) | Y18: =IF('Pilot offer'!$C$24="Yes",'Pilot offer'!$C$8,U18) | Z18: =IF('Pilot offer'!$C$24="Yes",'Pilot offer'!$C$11,"") | AA18: =IF(X18="","",W18&" · "&TEXT(X18,"ddd d mmm, hh:mm")&" · "&Y18&IF(Z18<>""," · £"&TEXT(Z18,"0.00")&" per player"," · price TBC (cost £"&TEXT(V18,"0.00")&" pp)"))
A19: 17 | B19: 1 · E2 Haggerston | C19: Education | D19: Local businesses | E19: William Davis Primary School | F19: amenity: school | G19: admin@williamdavis.org.uk | H19: general | I19: +44 20 7739 1511 | J19: https://www.williamdavis.org.uk/ | K19: Wood Close, London | L19: E2 6ET | M19: Whitechapel | N19: 19 | O19: =IFERROR(INDEX(Venues!$C$2:$C$10,MATCH(M19,Venues!$A$2:$A$10,0)),"Not checked") | P19: =IFERROR(INDEX(Venues!$D$2:$D$10,MATCH(M19,Venues!$A$2:$A$10,0)),0) | Q19: =IFERROR(INDEX(Venues!$E$2:$E$10,MATCH(M19,Venues!$A$2:$A$10,0)),"") | R19: =IF(P19>0,"Yes","No") | S19: COLA Shoreditch Park | T19: =IFERROR(INDEX(Venues!$E$2:$E$10,MATCH(S19,Venues!$A$2:$A$10,0)),"") | U19: =IFERROR(INDEX(Venues!$F$2:$F$10,MATCH(S19,Venues!$A$2:$A$10,0)),"") | V19: =IFERROR(INDEX(Venues!$H$2:$H$10,MATCH(S19,Venues!$A$2:$A$10,0)),"") | W19: =IF('Pilot offer'!$C$24="Yes",'Pilot offer'!$C$3,S19) | X19: =IF('Pilot offer'!$C$24="Yes",'Pilot offer'!$C$5+'Pilot offer'!$C$6,T19) | Y19: =IF('Pilot offer'!$C$24="Yes",'Pilot offer'!$C$8,U19) | Z19: =IF('Pilot offer'!$C$24="Yes",'Pilot offer'!$C$11,"") | AA19: =IF(X19="","",W19&" · "&TEXT(X19,"ddd d mmm, hh:mm")&" · "&Y19&IF(Z19<>""," · £"&TEXT(Z19,"0.00")&" per player"," · price TBC (cost £"&TEXT(V19,"0.00")&" pp)"))
A20: 18 | B20: 1 · E2 Haggerston | C20: Office & professional | D20: Corporate | E20: Crafted | F20: company | G20: hello@crafted.co.uk | H20: general | I20: +44 20 3327 9900 | J20: https://www.crafted.co.uk/ | K20: 115 Coventry Road, London | L20: E2 6GG | M20: Stepney 3G | N20: 11 | O20: =IFERROR(INDEX(Venues!$C$2:$C$10,MATCH(M20,Venues!$A$2:$A$10,0)),"Not checked") | P20: =IFERROR(INDEX(Venues!$D$2:$D$10,MATCH(M20,Venues!$A$2:$A$10,0)),0) | Q20: =IFERROR(INDEX(Venues!$E$2:$E$10,MATCH(M20,Venues!$A$2:$A$10,0)),"") | R20: =IF(P20>0,"Yes","No") | S20: COLA Shoreditch Park | T20: =IFERROR(INDEX(Venues!$E$2:$E$10,MATCH(S20,Venues!$A$2:$A$10,0)),"") | U20: =IFERROR(INDEX(Venues!$F$2:$F$10,MATCH(S20,Venues!$A$2:$A$10,0)),"") | V20: =IFERROR(INDEX(Venues!$H$2:$H$10,MATCH(S20,Venues!$A$2:$A$10,0)),"") | W20: =IF('Pilot offer'!$C$24="Yes",'Pilot offer'!$C$3,S20) | X20: =IF('Pilot offer'!$C$24="Yes",'Pilot offer'!$C$5+'Pilot offer'!$C$6,T20) | Y20: =IF('Pilot offer'!$C$24="Yes",'Pilot offer'!$C$8,U20) | Z20: =IF('Pilot offer'!$C$24="Yes",'Pilot offer'!$C$11,"") | AA20: =IF(X20="","",W20&" · "&TEXT(X20,"ddd d mmm, hh:mm")&" · "&Y20&IF(Z20<>""," · £"&TEXT(Z20,"0.00")&" per player"," · price TBC (cost £"&TEXT(V20,"0.00")&" pp)"))
A21: 19 | B21: 1 · E2 Haggerston | C21: Office & professional | D21: Corporate | E21: Transparent Digital Services | F21: advertising_agency | G21: contact@transparentdigitalservices.com | H21: openstreetmap_tag | I21: +44 7540 388706 | J21: https://transparentdigitalservices.com/ | K21: 115 Coventry Road, London | L21: E2 6GH | M21: Stepney 3G | N21: 11 | O21: =IFERROR(INDEX(Venues!$C$2:$C$10,MATCH(M21,Venues!$A$2:$A$10,0)),"Not checked") | P21: =IFERROR(INDEX(Venues!$D$2:$D$10,MATCH(M21,Venues!$A$2:$A$10,0)),0) | Q21: =IFERROR(INDEX(Venues!$E$2:$E$10,MATCH(M21,Venues!$A$2:$A$10,0)),"") | R21: =IF(P21>0,"Yes","No") | S21: COLA Shoreditch Park | T21: =IFERROR(INDEX(Venues!$E$2:$E$10,MATCH(S21,Venues!$A$2:$A$10,0)),"") | U21: =IFERROR(INDEX(Venues!$F$2:$F$10,MATCH(S21,Venues!$A$2:$A$10,0)),"") | V21: =IFERROR(INDEX(Venues!$H$2:$H$10,MATCH(S21,Venues!$A$2:$A$10,0)),"") | W21: =IF('Pilot offer'!$C$24="Yes",'Pilot offer'!$C$3,S21) | X21: =IF('Pilot offer'!$C$24="Yes",'Pilot offer'!$C$5+'Pilot offer'!$C$6,T21) | Y21: =IF('Pilot offer'!$C$24="Yes",'Pilot offer'!$C$8,U21) | Z21: =IF('Pilot offer'!$C$24="Yes",'Pilot offer'!$C$11,"") | AA21: =IF(X21="","",W21&" · "&TEXT(X21,"ddd d mmm, hh:mm")&" · "&Y21&IF(Z21<>""," · £"&TEXT(Z21,"0.00")&" per player"," · price TBC (cost £"&TEXT(V21,"0.00")&" pp)"))
A22: 20 | B22: 1 · E2 Haggerston | C22: Coworking / shared office | D22: Corporate | E22: Oxford House | F22: coworking_space | G22: info@oxfordhouse.org.uk | H22: general | I22: +44 20 7739 9001 | J22: http://www.oxfordhouse.org.uk/ | K22: Oxford House, Derbyshire St, Bethnal Green, London E2 6HG, UK | L22: E2 6HG | M22: Stepney 3G | N22: 15 | O22: =IFERROR(INDEX(Venues!$C$2:$C$10,MATCH(M22,Venues!$A$2:$A$10,0)),"Not checked") | P22: =IFERROR(INDEX(Venues!$D$2:$D$10,MATCH(M22,Venues!$A$2:$A$10,0)),0) | Q22: =IFERROR(INDEX(Venues!$E$2:$E$10,MATCH(M22,Venues!$A$2:$A$10,0)),"") | R22: =IF(P22>0,"Yes","No") | S22: COLA Shoreditch Park | T22: =IFERROR(INDEX(Venues!$E$2:$E$10,MATCH(S22,Venues!$A$2:$A$10,0)),"") | U22: =IFERROR(INDEX(Venues!$F$2:$F$10,MATCH(S22,Venues!$A$2:$A$10,0)),"") | V22: =IFERROR(INDEX(Venues!$H$2:$H$10,MATCH(S22,Venues!$A$2:$A$10,0)),"") | W22: =IF('Pilot offer'!$C$24="Yes",'Pilot offer'!$C$3,S22) | X22: =IF('Pilot offer'!$C$24="Yes",'Pilot offer'!$C$5+'Pilot offer'!$C$6,T22) | Y22: =IF('Pilot offer'!$C$24="Yes",'Pilot offer'!$C$8,U22) | Z22: =IF('Pilot offer'!$C$24="Yes",'Pilot offer'!$C$11,"") | AA22: =IF(X22="","",W22&" · "&TEXT(X22,"ddd d mmm, hh:mm")&" · "&Y22&IF(Z22<>""," · £"&TEXT(Z22,"0.00")&" per player"," · price TBC (cost £"&TEXT(V22,"0.00")&" pp)"))
A23: 21 | B23: 1 · E2 Haggerston | C23: Retail | D23: Local businesses | E23: Eastend Printers | F23: shop: copyshop | G23: info@eastendprinters.co.uk | H23: general | J23: https://eastendprinters.co.uk/ | K23: Dunbridge Street 71, London | L23: E2 6JG | M23: Stepney 3G | N23: 17 | O23: =IFERROR(INDEX(Venues!$C$2:$C$10,MATCH(M23,Venues!$A$2:$A$10,0)),"Not checked") | P23: =IFERROR(INDEX(Venues!$D$2:$D$10,MATCH(M23,Venues!$A$2:$A$10,0)),0) | Q23: =IFERROR(INDEX(Venues!$E$2:$E$10,MATCH(M23,Venues!$A$2:$A$10,0)),"") | R23: =IF(P23>0,"Yes","No") | S23: COLA Shoreditch Park | T23: =IFERROR(INDEX(Venues!$E$2:$E$10,MATCH(S23,Venues!$A$2:$A$10,0)),"") | U23: =IFERROR(INDEX(Venues!$F$2:$F$10,MATCH(S23,Venues!$A$2:$A$10,0)),"") | V23: =IFERROR(INDEX(Venues!$H$2:$H$10,MATCH(S23,Venues!$A$2:$A$10,0)),"") | W23: =IF('Pilot offer'!$C$24="Yes",'Pilot offer'!$C$3,S23) | X23: =IF('Pilot offer'!$C$24="Yes",'Pilot offer'!$C$5+'Pilot offer'!$C$6,T23) | Y23: =IF('Pilot offer'!$C$24="Yes",'Pilot offer'!$C$8,U23) | Z23: =IF('Pilot offer'!$C$24="Yes",'Pilot offer'!$C$11,"") | AA23: =IF(X23="","",W23&" · "&TEXT(X23,"ddd d mmm, hh:mm")&" · "&Y23&IF(Z23<>""," · £"&TEXT(Z23,"0.00")&" per player"," · price TBC (cost £"&TEXT(V23,"0.00")&" pp)"))
A24: 22 | B24: 1 · E2 Haggerston | C24: Leisure & culture | D24: Local businesses | E24: Bethnal Green Working Men's Club | F24: amenity: community centre | G24: info@workersplaytime.net | H24: general | J24: https://workersplaytime.net/ | K24: Pollard Row 42, London | L24: E2 6NB | M24: Stepney 3G | N24: 19 | O24: =IFERROR(INDEX(Venues!$C$2:$C$10,MATCH(M24,Venues!$A$2:$A$10,0)),"Not checked") | P24: =IFERROR(INDEX(Venues!$D$2:$D$10,MATCH(M24,Venues!$A$2:$A$10,0)),0) | Q24: =IFERROR(INDEX(Venues!$E$2:$E$10,MATCH(M24,Venues!$A$2:$A$10,0)),"") | R24: =IF(P24>0,"Yes","No") | S24: COLA Shoreditch Park | T24: =IFERROR(INDEX(Venues!$E$2:$E$10,MATCH(S24,Venues!$A$2:$A$10,0)),"") | U24: =IFERROR(INDEX(Venues!$F$2:$F$10,MATCH(S24,Venues!$A$2:$A$10,0)),"") | V24: =IFERROR(INDEX(Venues!$H$2:$H$10,MATCH(S24,Venues!$A$2:$A$10,0)),"") | W24: =IF('Pilot offer'!$C$24="Yes",'Pilot offer'!$C$3,S24) | X24: =IF('Pilot offer'!$C$24="Yes",'Pilot offer'!$C$5+'Pilot offer'!$C$6,T24) | Y24: =IF('Pilot offer'!$C$24="Yes",'Pilot offer'!$C$8,U24) | Z24: =IF('Pilot offer'!$C$24="Yes",'Pilot offer'!$C$11,"") | AA24: =IF(X24="","",W24&" · "&TEXT(X24,"ddd d mmm, hh:mm")&" · "&Y24&IF(Z24<>""," · £"&TEXT(Z24,"0.00")&" per player"," · price TBC (cost £"&TEXT(V24,"0.00")&" pp)"))
A25: 23 | B25: 1 · E2 Haggerston | C25: Education | D25: Local businesses | E25: Oaklands School | F25: amenity: school | G25: reception@oaklands.towerhamlets.sch.uk | H25: general | J25: https://oaklands.towerhamlets.sch.uk/ | K25: Old Bethnal Green Road, London | L25: E2 6PR | M25: Stepney 3G | N25: 17 | O25: =IFERROR(INDEX(Venues!$C$2:$C$10,MATCH(M25,Venues!$A$2:$A$10,0)),"Not checked") | P25: =IFERROR(INDEX(Venues!$D$2:$D$10,MATCH(M25,Venues!$A$2:$A$10,0)),0) | Q25: =IFERROR(INDEX(Venues!$E$2:$E$10,MATCH(M25,Venues!$A$2:$A$10,0)),"") | R25: =IF(P25>0,"Yes","No") | S25: COLA Shoreditch Park | T25: =IFERROR(INDEX(Venues!$E$2:$E$10,MATCH(S25,Venues!$A$2:$A$10,0)),"") | U25: =IFERROR(INDEX(Venues!$F$2:$F$10,MATCH(S25,Venues!$A$2:$A$10,0)),"") | V25: =IFERROR(INDEX(Venues!$H$2:$H$10,MATCH(S25,Venues!$A$2:$A$10,0)),"") | W25: =IF('Pilot offer'!$C$24="Yes",'Pilot offer'!$C$3,S25) | X25: =IF('Pilot offer'!$C$24="Yes",'Pilot offer'!$C$5+'Pilot offer'!$C$6,T25) | Y25: =IF('Pilot offer'!$C$24="Yes",'Pilot offer'!$C$8,U25) | Z25: =IF('Pilot offer'!$C$24="Yes",'Pilot offer'!$C$11,"") | AA25: =IF(X25="","",W25&" · "&TEXT(X25,"ddd d mmm, hh:mm")&" · "&Y25&IF(Z25<>""," · £"&TEXT(Z25,"0.00")&" per player"," · price TBC (cost £"&TEXT(V25,"0.00")&" pp)"))
A26: 24 | B26: 1 · E2 Haggerston | C26: Hospitality | D26: Local businesses | E26: The Common E2 | F26: amenity: cafe | G26: info@thecommone2.com | H26: general | J26: http://www.thecommone2.com | K26: Old Bethnal Green Road 53, London | L26: E2 6QA | M26: Stepney 3G | N26: 17 | O26: =IFERROR(INDEX(Venues!$C$2:$C$10,MATCH(M26,Venues!$A$2:$A$10,0)),"Not checked") | P26: =IFERROR(INDEX(Venues!$D$2:$D$10,MATCH(M26,Venues!$A$2:$A$10,0)),0) | Q26: =IFERROR(INDEX(Venues!$E$2:$E$10,MATCH(M26,Venues!$A$2:$A$10,0)),"") | R26: =IF(P26>0,"Yes","No") | S26: COLA Shoreditch Park | T26: =IFERROR(INDEX(Venues!$E$2:$E$10,MATCH(S26,Venues!$A$2:$A$10,0)),"") | U26: =IFERROR(INDEX(Venues!$F$2:$F$10,MATCH(S26,Venues!$A$2:$A$10,0)),"") | V26: =IFERROR(INDEX(Venues!$H$2:$H$10,MATCH(S26,Venues!$A$2:$A$10,0)),"") | W26: =IF('Pilot offer'!$C$24="Yes",'Pilot offer'!$C$3,S26) | X26: =IF('Pilot offer'!$C$24="Yes",'Pilot offer'!$C$5+'Pilot offer'!$C$6,T26) | Y26: =IF('Pilot offer'!$C$24="Yes",'Pilot offer'!$C$8,U26) | Z26: =IF('Pilot offer'!$C$24="Yes",'Pilot offer'!$C$11,"") | AA26: =IF(X26="","",W26&" · "&TEXT(X26,"ddd d mmm, hh:mm")&" · "&Y26&IF(Z26<>""," · £"&TEXT(Z26,"0.00")&" per player"," · price TBC (cost £"&TEXT(V26,"0.00")&" pp)"))
A27: 25 | B27: 1 · E2 Haggerston | C27: Hospitality | D27: Local businesses | E27: A Portuguese Love Affair | F27: amenity: cafe | G27: info@aportugueseloveaffair.co.uk | H27: general | I27: +44 20 3490 2662 | J27: https://www.aportugueseloveaffair.co.uk/ | K27: Hackney Road 326, London | L27: E2 7AX | M27: Shoreditch Rooftop | N27: 20 | O27: =IFERROR(INDEX(Venues!$C$2:$C$10,MATCH(M27,Venues!$A$2:$A$10,0)),"Not checked") | P27: =IFERROR(INDEX(Venues!$D$2:$D$10,MATCH(M27,Venues!$A$2:$A$10,0)),0) | Q27: =IFERROR(INDEX(Venues!$E$2:$E$10,MATCH(M27,Venues!$A$2:$A$10,0)),"") | R27: =IF(P27>0,"Yes","No") | S27: Shoreditch Rooftop | T27: =IFERROR(INDEX(Venues!$E$2:$E$10,MATCH(S27,Venues!$A$2:$A$10,0)),"") | U27: =IFERROR(INDEX(Venues!$F$2:$F$10,MATCH(S27,Venues!$A$2:$A$10,0)),"") | V27: =IFERROR(INDEX(Venues!$H$2:$H$10,MATCH(S27,Venues!$A$2:$A$10,0)),"") | W27: =IF('Pilot offer'!$C$24="Yes",'Pilot offer'!$C$3,S27) | X27: =IF('Pilot offer'!$C$24="Yes",'Pilot offer'!$C$5+'Pilot offer'!$C$6,T27) | Y27: =IF('Pilot offer'!$C$24="Yes",'Pilot offer'!$C$8,U27) | Z27: =IF('Pilot offer'!$C$24="Yes",'Pilot offer'!$C$11,"") | AA27: =IF(X27="","",W27&" · "&TEXT(X27,"ddd d mmm, hh:mm")&" · "&Y27&IF(Z27<>""," · £"&TEXT(Z27,"0.00")&" per player"," · price TBC (cost £"&TEXT(V27,"0.00")&" pp)"))
A28: 26 | B28: 1 · E2 Haggerston | C28: Office & professional | D28: Corporate | E28: Small World | F28: consultant | G28: hello@meetsmallworld.com | H28: general | J28: http://www.meetsmallworld.com/ | K28: 10 Redchurch St, London E2 7DD, UK | L28: E2 7DD | M28: Shoreditch Rooftop | N28: 21 | O28: =IFERROR(INDEX(Venues!$C$2:$C$10,MATCH(M28,Venues!$A$2:$A$10,0)),"Not checked") | P28: =IFERROR(INDEX(Venues!$D$2:$D$10,MATCH(M28,Venues!$A$2:$A$10,0)),0) | Q28: =IFERROR(INDEX(Venues!$E$2:$E$10,MATCH(M28,Venues!$A$2:$A$10,0)),"") | R28: =IF(P28>0,"Yes","No") | S28: Shoreditch Rooftop | T28: =IFERROR(INDEX(Venues!$E$2:$E$10,MATCH(S28,Venues!$A$2:$A$10,0)),"") | U28: =IFERROR(INDEX(Venues!$F$2:$F$10,MATCH(S28,Venues!$A$2:$A$10,0)),"") | V28: =IFERROR(INDEX(Venues!$H$2:$H$10,MATCH(S28,Venues!$A$2:$A$10,0)),"") | W28: =IF('Pilot offer'!$C$24="Yes",'Pilot offer'!$C$3,S28) | X28: =IF('Pilot offer'!$C$24="Yes",'Pilot offer'!$C$5+'Pilot offer'!$C$6,T28) | Y28: =IF('Pilot offer'!$C$24="Yes",'Pilot offer'!$C$8,U28) | Z28: =IF('Pilot offer'!$C$24="Yes",'Pilot offer'!$C$11,"") | AA28: =IF(X28="","",W28&" · "&TEXT(X28,"ddd d mmm, hh:mm")&" · "&Y28&IF(Z28<>""," · £"&TEXT(Z28,"0.00")&" per player"," · price TBC (cost £"&TEXT(V28,"0.00")&" pp)"))
A29: 27 | B29: 1 · E2 Haggerston | C29: Hospitality | D29: Local businesses | E29: BAO Noodle Shop | F29: amenity: restaurant | G29: info@baolondon.com | H29: general | J29: https://baolondon.com/ | K29: Redchurch Street 1, London | L29: E2 7DJ | M29: Shoreditch Rooftop | N29: 20 | O29: =IFERROR(INDEX(Venues!$C$2:$C$10,MATCH(M29,Venues!$A$2:$A$10,0)),"Not checked") | P29: =IFERROR(INDEX(Venues!$D$2:$D$10,MATCH(M29,Venues!$A$2:$A$10,0)),0) | Q29: =IFERROR(INDEX(Venues!$E$2:$E$10,MATCH(M29,Venues!$A$2:$A$10,0)),"") | R29: =IF(P29>0,"Yes","No") | S29: Shoreditch Rooftop | T29: =IFERROR(INDEX(Venues!$E$2:$E$10,MATCH(S29,Venues!$A$2:$A$10,0)),"") | U29: =IFERROR(INDEX(Venues!$F$2:$F$10,MATCH(S29,Venues!$A$2:$A$10,0)),"") | V29: =IFERROR(INDEX(Venues!$H$2:$H$10,MATCH(S29,Venues!$A$2:$A$10,0)),"") | W29: =IF('Pilot offer'!$C$24="Yes",'Pilot offer'!$C$3,S29) | X29: =IF('Pilot offer'!$C$24="Yes",'Pilot offer'!$C$5+'Pilot offer'!$C$6,T29) | Y29: =IF('Pilot offer'!$C$24="Yes",'Pilot offer'!$C$8,U29) | Z29: =IF('Pilot offer'!$C$24="Yes",'Pilot offer'!$C$11,"") | AA29: =IF(X29="","",W29&" · "&TEXT(X29,"ddd d mmm, hh:mm")&" · "&Y29&IF(Z29<>""," · £"&TEXT(Z29,"0.00")&" per player"," · price TBC (cost £"&TEXT(V29,"0.00")&" pp)"))
A30: 28 | B30: 1 · E2 Haggerston | C30: Health | D30: Local businesses | E30: Mildmay Mission Hospital | F30: amenity: hospital | G30: info@mildmay.org | H30: general | I30: +44 20 7613 6300 | J30: https://www.mildmay.org/ | K30: Tabernacle Gardens 19, London | L30: E2 7DZ | M30: Shoreditch Rooftop | N30: 15 | O30: =IFERROR(INDEX(Venues!$C$2:$C$10,MATCH(M30,Venues!$A$2:$A$10,0)),"Not checked") | P30: =IFERROR(INDEX(Venues!$D$2:$D$10,MATCH(M30,Venues!$A$2:$A$10,0)),0) | Q30: =IFERROR(INDEX(Venues!$E$2:$E$10,MATCH(M30,Venues!$A$2:$A$10,0)),"") | R30: =IF(P30>0,"Yes","No") | S30: Shoreditch Rooftop | T30: =IFERROR(INDEX(Venues!$E$2:$E$10,MATCH(S30,Venues!$A$2:$A$10,0)),"") | U30: =IFERROR(INDEX(Venues!$F$2:$F$10,MATCH(S30,Venues!$A$2:$A$10,0)),"") | V30: =IFERROR(INDEX(Venues!$H$2:$H$10,MATCH(S30,Venues!$A$2:$A$10,0)),"") | W30: =IF('Pilot offer'!$C$24="Yes",'Pilot offer'!$C$3,S30) | X30: =IF('Pilot offer'!$C$24="Yes",'Pilot offer'!$C$5+'Pilot offer'!$C$6,T30) | Y30: =IF('Pilot offer'!$C$24="Yes",'Pilot offer'!$C$8,U30) | Z30: =IF('Pilot offer'!$C$24="Yes",'Pilot offer'!$C$11,"") | AA30: =IF(X30="","",W30&" · "&TEXT(X30,"ddd d mmm, hh:mm")&" · "&Y30&IF(Z30<>""," · £"&TEXT(Z30,"0.00")&" per player"," · price TBC (cost £"&TEXT(V30,"0.00")&" pp)"))
A31: 29 | B31: 1 · E2 Haggerston | C31: Hospitality | D31: Local businesses | E31: The Umbrella Workshop | F31: amenity: bar | G31: info@theumbrellaproject.co.uk | H31: general | I31: +44 20 7739 4951 | J31: https://theumbrellaproject.co.uk/ | K31: Boundary Street, London | L31: E2 7JD | M31: Shoreditch Rooftop | N31: 17 | O31: =IFERROR(INDEX(Venues!$C$2:$C$10,MATCH(M31,Venues!$A$2:$A$10,0)),"Not checked") | P31: =IFERROR(INDEX(Venues!$D$2:$D$10,MATCH(M31,Venues!$A$2:$A$10,0)),0) | Q31: =IFERROR(INDEX(Venues!$E$2:$E$10,MATCH(M31,Venues!$A$2:$A$10,0)),"") | R31: =IF(P31>0,"Yes","No") | S31: Shoreditch Rooftop | T31: =IFERROR(INDEX(Venues!$E$2:$E$10,MATCH(S31,Venues!$A$2:$A$10,0)),"") | U31: =IFERROR(INDEX(Venues!$F$2:$F$10,MATCH(S31,Venues!$A$2:$A$10,0)),"") | V31: =IFERROR(INDEX(Venues!$H$2:$H$10,MATCH(S31,Venues!$A$2:$A$10,0)),"") | W31: =IF('Pilot offer'!$C$24="Yes",'Pilot offer'!$C$3,S31) | X31: =IF('Pilot offer'!$C$24="Yes",'Pilot offer'!$C$5+'Pilot offer'!$C$6,T31) | Y31: =IF('Pilot offer'!$C$24="Yes",'Pilot offer'!$C$8,U31) | Z31: =IF('Pilot offer'!$C$24="Yes",'Pilot offer'!$C$11,"") | AA31: =IF(X31="","",W31&" · "&TEXT(X31,"ddd d mmm, hh:mm")&" · "&Y31&IF(Z31<>""," · £"&TEXT(Z31,"0.00")&" per player"," · price TBC (cost £"&TEXT(V31,"0.00")&" pp)"))
A32: 30 | B32: 1 · E2 Haggerston | C32: Retail | D32: Local businesses | E32: facebar | F32: shop: beauty | G32: hello@facebarlondon.com | H32: general | I32: +44 7789 618125 | J32: https://facebarlondon.com/ | K32: Boundary Street, London | L32: E2 7JD | M32: Shoreditch Rooftop | N32: 17 | O32: =IFERROR(INDEX(Venues!$C$2:$C$10,MATCH(M32,Venues!$A$2:$A$10,0)),"Not checked") | P32: =IFERROR(INDEX(Venues!$D$2:$D$10,MATCH(M32,Venues!$A$2:$A$10,0)),0) | Q32: =IFERROR(INDEX(Venues!$E$2:$E$10,MATCH(M32,Venues!$A$2:$A$10,0)),"") | R32: =IF(P32>0,"Yes","No") | S32: Shoreditch Rooftop | T32: =IFERROR(INDEX(Venues!$E$2:$E$10,MATCH(S32,Venues!$A$2:$A$10,0)),"") | U32: =IFERROR(INDEX(Venues!$F$2:$F$10,MATCH(S32,Venues!$A$2:$A$10,0)),"") | V32: =IFERROR(INDEX(Venues!$H$2:$H$10,MATCH(S32,Venues!$A$2:$A$10,0)),"") | W32: =IF('Pilot offer'!$C$24="Yes",'Pilot offer'!$C$3,S32) | X32: =IF('Pilot offer'!$C$24="Yes",'Pilot offer'!$C$5+'Pilot offer'!$C$6,T32) | Y32: =IF('Pilot offer'!$C$24="Yes",'Pilot offer'!$C$8,U32) | Z32: =IF('Pilot offer'!$C$24="Yes",'Pilot offer'!$C$11,"") | AA32: =IF(X32="","",W32&" · "&TEXT(X32,"ddd d mmm, hh:mm")&" · "&Y32&IF(Z32<>""," · £"&TEXT(Z32,"0.00")&" per player"," · price TBC (cost £"&TEXT(V32,"0.00")&" pp)"))
A33: 31 | B33: 1 · E2 Haggerston | C33: Hospitality | D33: Local businesses | E33: Paper & Cup | F33: amenity: cafe | G33: paperandcup@sct.org.uk | H33: openstreetmap_tag | I33: +44 7732 691013 | J33: https://sct.org.uk/social-enterprises/paper-cup/ | K33: Calvert Avenue 18, London | L33: E2 7JP | M33: Shoreditch Rooftop | N33: 17 | O33: =IFERROR(INDEX(Venues!$C$2:$C$10,MATCH(M33,Venues!$A$2:$A$10,0)),"Not checked") | P33: =IFERROR(INDEX(Venues!$D$2:$D$10,MATCH(M33,Venues!$A$2:$A$10,0)),0) | Q33: =IFERROR(INDEX(Venues!$E$2:$E$10,MATCH(M33,Venues!$A$2:$A$10,0)),"") | R33: =IF(P33>0,"Yes","No") | S33: Shoreditch Rooftop | T33: =IFERROR(INDEX(Venues!$E$2:$E$10,MATCH(S33,Venues!$A$2:$A$10,0)),"") | U33: =IFERROR(INDEX(Venues!$F$2:$F$10,MATCH(S33,Venues!$A$2:$A$10,0)),"") | V33: =IFERROR(INDEX(Venues!$H$2:$H$10,MATCH(S33,Venues!$A$2:$A$10,0)),"") | W33: =IF('Pilot offer'!$C$24="Yes",'Pilot offer'!$C$3,S33) | X33: =IF('Pilot offer'!$C$24="Yes",'Pilot offer'!$C$5+'Pilot offer'!$C$6,T33) | Y33: =IF('Pilot offer'!$C$24="Yes",'Pilot offer'!$C$8,U33) | Z33: =IF('Pilot offer'!$C$24="Yes",'Pilot offer'!$C$11,"") | AA33: =IF(X33="","",W33&" · "&TEXT(X33,"ddd d mmm, hh:mm")&" · "&Y33&IF(Z33<>""," · £"&TEXT(Z33,"0.00")&" per player"," · price TBC (cost £"&TEXT(V33,"0.00")&" pp)"))
A34: 32 | B34: 1 · E2 Haggerston | C34: Retail | D34: Local businesses | E34: Odyssey Male Grooming | F34: shop: hairdresser | G34: hello@odysseymalegrooming.com | H34: openstreetmap_tag | I34: +44 20 3911 8144 | J34: https://www.odysseymalegrooming.com/ | K34: Hackney Road 63, London | L34: E2 7NX | M34: Shoreditch Rooftop | N34: 14 | O34: =IFERROR(INDEX(Venues!$C$2:$C$10,MATCH(M34,Venues!$A$2:$A$10,0)),"Not checked") | P34: =IFERROR(INDEX(Venues!$D$2:$D$10,MATCH(M34,Venues!$A$2:$A$10,0)),0) | Q34: =IFERROR(INDEX(Venues!$E$2:$E$10,MATCH(M34,Venues!$A$2:$A$10,0)),"") | R34: =IF(P34>0,"Yes","No") | S34: Shoreditch Rooftop | T34: =IFERROR(INDEX(Venues!$E$2:$E$10,MATCH(S34,Venues!$A$2:$A$10,0)),"") | U34: =IFERROR(INDEX(Venues!$F$2:$F$10,MATCH(S34,Venues!$A$2:$A$10,0)),"") | V34: =IFERROR(INDEX(Venues!$H$2:$H$10,MATCH(S34,Venues!$A$2:$A$10,0)),"") | W34: =IF('Pilot offer'!$C$24="Yes",'Pilot offer'!$C$3,S34) | X34: =IF('Pilot offer'!$C$24="Yes",'Pilot offer'!$C$5+'Pilot offer'!$C$6,T34) | Y34: =IF('Pilot offer'!$C$24="Yes",'Pilot offer'!$C$8,U34) | Z34: =IF('Pilot offer'!$C$24="Yes",'Pilot offer'!$C$11,"") | AA34: =IF(X34="","",W34&" · "&TEXT(X34,"ddd d mmm, hh:mm")&" · "&Y34&IF(Z34<>""," · £"&TEXT(Z34,"0.00")&" per player"," · price TBC (cost £"&TEXT(V34,"0.00")&" pp)"))
A35: 33 | B35: 1 · E2 Haggerston | C35: Retail | D35: Local businesses | E35: Idle Moments | F35: shop: wine | G35: info@idle-moments.com | H35: general | I35: +44 20 7646 3762 | J35: https://idle-moments.com/ | K35: Columbia Road 86, London | L35: E2 7QB | M35: Shoreditch Rooftop | N35: 18 | O35: =IFERROR(INDEX(Venues!$C$2:$C$10,MATCH(M35,Venues!$A$2:$A$10,0)),"Not checked") | P35: =IFERROR(INDEX(Venues!$D$2:$D$10,MATCH(M35,Venues!$A$2:$A$10,0)),0) | Q35: =IFERROR(INDEX(Venues!$E$2:$E$10,MATCH(M35,Venues!$A$2:$A$10,0)),"") | R35: =IF(P35>0,"Yes","No") | S35: Shoreditch Rooftop | T35: =IFERROR(INDEX(Venues!$E$2:$E$10,MATCH(S35,Venues!$A$2:$A$10,0)),"") | U35: =IFERROR(INDEX(Venues!$F$2:$F$10,MATCH(S35,Venues!$A$2:$A$10,0)),"") | V35: =IFERROR(INDEX(Venues!$H$2:$H$10,MATCH(S35,Venues!$A$2:$A$10,0)),"") | W35: =IF('Pilot offer'!$C$24="Yes",'Pilot offer'!$C$3,S35) | X35: =IF('Pilot offer'!$C$24="Yes",'Pilot offer'!$C$5+'Pilot offer'!$C$6,T35) | Y35: =IF('Pilot offer'!$C$24="Yes",'Pilot offer'!$C$8,U35) | Z35: =IF('Pilot offer'!$C$24="Yes",'Pilot offer'!$C$11,"") | AA35: =IF(X35="","",W35&" · "&TEXT(X35,"ddd d mmm, hh:mm")&" · "&Y35&IF(Z35<>""," · £"&TEXT(Z35,"0.00")&" per player"," · price TBC (cost £"&TEXT(V35,"0.00")&" pp)"))
A36: 34 | B36: 1 · E2 Haggerston | C36: Hospitality | D36: Local businesses | E36: Brawn | F36: amenity: restaurant | G36: enquiries@brawn.co | H36: general | J36: https://www.brawn.co/ | K36: Columbia Road 49, London | L36: E2 7RG | M36: Shoreditch Rooftop | N36: 18 | O36: =IFERROR(INDEX(Venues!$C$2:$C$10,MATCH(M36,Venues!$A$2:$A$10,0)),"Not checked") | P36: =IFERROR(INDEX(Venues!$D$2:$D$10,MATCH(M36,Venues!$A$2:$A$10,0)),0) | Q36: =IFERROR(INDEX(Venues!$E$2:$E$10,MATCH(M36,Venues!$A$2:$A$10,0)),"") | R36: =IF(P36>0,"Yes","No") | S36: Shoreditch Rooftop | T36: =IFERROR(INDEX(Venues!$E$2:$E$10,MATCH(S36,Venues!$A$2:$A$10,0)),"") | U36: =IFERROR(INDEX(Venues!$F$2:$F$10,MATCH(S36,Venues!$A$2:$A$10,0)),"") | V36: =IFERROR(INDEX(Venues!$H$2:$H$10,MATCH(S36,Venues!$A$2:$A$10,0)),"") | W36: =IF('Pilot offer'!$C$24="Yes",'Pilot offer'!$C$3,S36) | X36: =IF('Pilot offer'!$C$24="Yes",'Pilot offer'!$C$5+'Pilot offer'!$C$6,T36) | Y36: =IF('Pilot offer'!$C$24="Yes",'Pilot offer'!$C$8,U36) | Z36: =IF('Pilot offer'!$C$24="Yes",'Pilot offer'!$C$11,"") | AA36: =IF(X36="","",W36&" · "&TEXT(X36,"ddd d mmm, hh:mm")&" · "&Y36&IF(Z36<>""," · £"&TEXT(Z36,"0.00")&" per player"," · price TBC (cost £"&TEXT(V36,"0.00")&" pp)"))
A37: 35 | B37: 1 · E2 Haggerston | C37: Retail | D37: Local businesses | E37: Mosaic Factory | F37: shop: tiles | G37: info-uk@mosaicdelsur.com | H37: openstreetmap_tag | I37: +44 20 3514 0483 | J37: https://www.cement-tiles.com/ | K37: Columbia Road 106, London | L37: E2 7RG | M37: Shoreditch Rooftop | N37: 18 | O37: =IFERROR(INDEX(Venues!$C$2:$C$10,MATCH(M37,Venues!$A$2:$A$10,0)),"Not checked") | P37: =IFERROR(INDEX(Venues!$D$2:$D$10,MATCH(M37,Venues!$A$2:$A$10,0)),0) | Q37: =IFERROR(INDEX(Venues!$E$2:$E$10,MATCH(M37,Venues!$A$2:$A$10,0)),"") | R37: =IF(P37>0,"Yes","No") | S37: Shoreditch Rooftop | T37: =IFERROR(INDEX(Venues!$E$2:$E$10,MATCH(S37,Venues!$A$2:$A$10,0)),"") | U37: =IFERROR(INDEX(Venues!$F$2:$F$10,MATCH(S37,Venues!$A$2:$A$10,0)),"") | V37: =IFERROR(INDEX(Venues!$H$2:$H$10,MATCH(S37,Venues!$A$2:$A$10,0)),"") | W37: =IF('Pilot offer'!$C$24="Yes",'Pilot offer'!$C$3,S37) | X37: =IF('Pilot offer'!$C$24="Yes",'Pilot offer'!$C$5+'Pilot offer'!$C$6,T37) | Y37: =IF('Pilot offer'!$C$24="Yes",'Pilot offer'!$C$8,U37) | Z37: =IF('Pilot offer'!$C$24="Yes",'Pilot offer'!$C$11,"") | AA37: =IF(X37="","",W37&" · "&TEXT(X37,"ddd d mmm, hh:mm")&" · "&Y37&IF(Z37<>""," · £"&TEXT(Z37,"0.00")&" per player"," · price TBC (cost £"&TEXT(V37,"0.00")&" pp)"))
A38: 36 | B38: 1 · E2 Haggerston | C38: Retail | D38: Local businesses | E38: Play Vinyl | F38: shop: music | G38: info@playvinyl.london | H38: openstreetmap_tag | I38: +44 7480 651744 | J38: https://playvinyl.london/ | K38: Ezra Street 14, London | L38: E2 7RH | M38: Shoreditch Rooftop | N38: 18 | O38: =IFERROR(INDEX(Venues!$C$2:$C$10,MATCH(M38,Venues!$A$2:$A$10,0)),"Not checked") | P38: =IFERROR(INDEX(Venues!$D$2:$D$10,MATCH(M38,Venues!$A$2:$A$10,0)),0) | Q38: =IFERROR(INDEX(Venues!$E$2:$E$10,MATCH(M38,Venues!$A$2:$A$10,0)),"") | R38: =IF(P38>0,"Yes","No") | S38: Shoreditch Rooftop | T38: =IFERROR(INDEX(Venues!$E$2:$E$10,MATCH(S38,Venues!$A$2:$A$10,0)),"") | U38: =IFERROR(INDEX(Venues!$F$2:$F$10,MATCH(S38,Venues!$A$2:$A$10,0)),"") | V38: =IFERROR(INDEX(Venues!$H$2:$H$10,MATCH(S38,Venues!$A$2:$A$10,0)),"") | W38: =IF('Pilot offer'!$C$24="Yes",'Pilot offer'!$C$3,S38) | X38: =IF('Pilot offer'!$C$24="Yes",'Pilot offer'!$C$5+'Pilot offer'!$C$6,T38) | Y38: =IF('Pilot offer'!$C$24="Yes",'Pilot offer'!$C$8,U38) | Z38: =IF('Pilot offer'!$C$24="Yes",'Pilot offer'!$C$11,"") | AA38: =IF(X38="","",W38&" · "&TEXT(X38,"ddd d mmm, hh:mm")&" · "&Y38&IF(Z38<>""," · £"&TEXT(Z38,"0.00")&" per player"," · price TBC (cost £"&TEXT(V38,"0.00")&" pp)"))
A39: 37 | B39: 1 · E2 Haggerston | C39: Hospitality | D39: Local businesses | E39: The Nelson's | F39: amenity: pub | G39: ben@thenelsonspub.com | H39: person_or_other | I39: +44 7427 012091 | J39: https://www.thenelsonspub.com/ | K39: Horatio Street 32, London | L39: E2 7SB | M39: Shoreditch Rooftop | N39: 17 | O39: =IFERROR(INDEX(Venues!$C$2:$C$10,MATCH(M39,Venues!$A$2:$A$10,0)),"Not checked") | P39: =IFERROR(INDEX(Venues!$D$2:$D$10,MATCH(M39,Venues!$A$2:$A$10,0)),0) | Q39: =IFERROR(INDEX(Venues!$E$2:$E$10,MATCH(M39,Venues!$A$2:$A$10,0)),"") | R39: =IF(P39>0,"Yes","No") | S39: Shoreditch Rooftop | T39: =IFERROR(INDEX(Venues!$E$2:$E$10,MATCH(S39,Venues!$A$2:$A$10,0)),"") | U39: =IFERROR(INDEX(Venues!$F$2:$F$10,MATCH(S39,Venues!$A$2:$A$10,0)),"") | V39: =IFERROR(INDEX(Venues!$H$2:$H$10,MATCH(S39,Venues!$A$2:$A$10,0)),"") | W39: =IF('Pilot offer'!$C$24="Yes",'Pilot offer'!$C$3,S39) | X39: =IF('Pilot offer'!$C$24="Yes",'Pilot offer'!$C$5+'Pilot offer'!$C$6,T39) | Y39: =IF('Pilot offer'!$C$24="Yes",'Pilot offer'!$C$8,U39) | Z39: =IF('Pilot offer'!$C$24="Yes",'Pilot offer'!$C$11,"") | AA39: =IF(X39="","",W39&" · "&TEXT(X39,"ddd d mmm, hh:mm")&" · "&Y39&IF(Z39<>""," · £"&TEXT(Z39,"0.00")&" per player"," · price TBC (cost £"&TEXT(V39,"0.00")&" pp)"))
A40: 38 | B40: 1 · E2 Haggerston | C40: Hospitality | D40: Local businesses | E40: Indian Greedy Cow | F40: amenity: fast food | G40: info@indiangreedycow.co.uk | H40: general | I40: +44 20 7739 4884 | J40: https://www.indiangreedycow.co.uk/ | K40: Hackney Road 310, London | L40: E2 7SJ | M40: Shoreditch Rooftop | N40: 19 | O40: =IFERROR(INDEX(Venues!$C$2:$C$10,MATCH(M40,Venues!$A$2:$A$10,0)),"Not checked") | P40: =IFERROR(INDEX(Venues!$D$2:$D$10,MATCH(M40,Venues!$A$2:$A$10,0)),0) | Q40: =IFERROR(INDEX(Venues!$E$2:$E$10,MATCH(M40,Venues!$A$2:$A$10,0)),"") | R40: =IF(P40>0,"Yes","No") | S40: Shoreditch Rooftop | T40: =IFERROR(INDEX(Venues!$E$2:$E$10,MATCH(S40,Venues!$A$2:$A$10,0)),"") | U40: =IFERROR(INDEX(Venues!$F$2:$F$10,MATCH(S40,Venues!$A$2:$A$10,0)),"") | V40: =IFERROR(INDEX(Venues!$H$2:$H$10,MATCH(S40,Venues!$A$2:$A$10,0)),"") | W40: =IF('Pilot offer'!$C$24="Yes",'Pilot offer'!$C$3,S40) | X40: =IF('Pilot offer'!$C$24="Yes",'Pilot offer'!$C$5+'Pilot offer'!$C$6,T40) | Y40: =IF('Pilot offer'!$C$24="Yes",'Pilot offer'!$C$8,U40) | Z40: =IF('Pilot offer'!$C$24="Yes",'Pilot offer'!$C$11,"") | AA40: =IF(X40="","",W40&" · "&TEXT(X40,"ddd d mmm, hh:mm")&" · "&Y40&IF(Z40<>""," · £"&TEXT(Z40,"0.00")&" per player"," · price TBC (cost £"&TEXT(V40,"0.00")&" pp)"))
...

Sheet Pilot offer
B1: Pilot offer · Haggerston Park
B2: Yellow cells are inputs. Once date, kick-off, format and price are filled, every Outreach row leads with this slot.
B3: Pitch | C3: Haggerston Park | D3: Luuk
B4: Address | C4: Yorkton St, E2 8NH | D4: Luuk
B5: Date | D5: Luuk
B6: Kick-off | D6: Luuk
B7: Duration (min) | C7: 60 | D7: Luuk
B8: Format | D8: Luuk
B9: Players on the pitch | C9: =IFERROR(VALUE(LEFT(C8,FIND("-",C8)-1))*2,"")
B10: Hire cost (£) | D10: Luuk
B11: Price per player (£) | D11: Joep
B12: Minimum paying players to cover hire | C12: =IF(OR(C10="",C11="",C11=0),"",ROUNDUP(C10/C11,0))
B13: Revenue if full (£) | C13: =IF(OR(C9="",C11=""),"",C9*C11)
B14: Margin if full (£) | C14: =IF(OR(C13="",C10=""),"",C13-C10)
B15: Margin if full (%) | C15: =IF(OR(C14="",C13="",C13=0),"",C14/C13)
B16: Booking deadline (venue) | D16: Luuk
B17: Cancellation terms (venue) | D17: Luuk
B18: We commit to the venue when… | D18: Joep
B19: Joining link (app)
B20: Deadline for players to commit
B21: Who confirms the booking | C21: Hackney Parks bookings (GLL) · 020 8986 7955 (Mon–Fri 09:00–15:30) · hackney.marshes@gll.org | D21: Luuk
B22: Floodlit | C22: Yes per Playfinder / Hackney Council (18:00–22:00 in term time); fcurban.com page says no — confirm on the call | D22: Luuk
B24: Pilot ready to lead outreach? | C24: =IF(AND(C5<>"",C6<>"",C8<>"",C11<>""),"Yes","No — fill Date, Kick-off, Format and Price")
B26: Cost floor for comparison: see Venues › Cost per player at earliest. Old St – Moreland 6-a-side works out at £7.50 per player at cost; COLA 5-a-side £9.10.

Sheet Venues
A1: Venue | B1: Address | C1: Status | D1: Open after-work slots | E1: Earliest slot | F1: Earliest format | G1: Earliest hire (£) | H1: Cost per player at earliest (£) | I1: Floodlit | J1: Booking source | K1: Booking link | L1: Booking contact | M1: Phone | N1: Email | O1: How to book / notes | P1: Leads tagged here | Q1: Leads using as fallback
A2: Haggerston Park | B2: Yorkton St, E2 8NH | C2: Contact required | D2: =COUNTIFS(Slots!$A$2:$A$90,A2,Slots!$I$2:$I$90,"Available") | E2: =IF(D2=0,"",_xlfn.MINIFS(Slots!$F$2:$F$90,Slots!$A$2:$A$90,A2,Slots!$I$2:$I$90,"Available")) | F2: =IFERROR(INDEX(Slots!$G$2:$G$90,MATCH(A2&"#1",Slots!$R$2:$R$90,0)),"") | G2: =IFERROR(INDEX(Slots!$J$2:$J$90,MATCH(A2&"#1",Slots!$R$2:$R$90,0)),"") | H2: =IFERROR(INDEX(Slots!$L$2:$L$90,MATCH(A2&"#1",Slots!$R$2:$R$90,0)),"") | I2: yes | J2: Hackney Council (GLL) | K2: https://www.hackney.gov.uk/courts-and-pitches | L2: Hackney Parks bookings (GLL) | M2: 020 8986 7955 | N2: hackney.marshes@gll.org | O2: Phone line Mon-Fri 09:00-15:30. Pitch bookable 18:00-22:00 in term time per Hackney Council | P2: =COUNTIF(Outreach!$M$3:$M$2000,A2) | Q2: =COUNTIF(Outreach!$S$3:$S$2000,A2)
A3: Whitechapel | B3: Mulberry Sports & Leisure Centre, Richard St, E1 2JP | C3: Contact required | D3: =COUNTIFS(Slots!$A$2:$A$90,A3,Slots!$I$2:$I$90,"Available") | E3: =IF(D3=0,"",_xlfn.MINIFS(Slots!$F$2:$F$90,Slots!$A$2:$A$90,A3,Slots!$I$2:$I$90,"Available")) | F3: =IFERROR(INDEX(Slots!$G$2:$G$90,MATCH(A3&"#1",Slots!$R$2:$R$90,0)),"") | G3: =IFERROR(INDEX(Slots!$J$2:$J$90,MATCH(A3&"#1",Slots!$R$2:$R$90,0)),"") | H3: =IFERROR(INDEX(Slots!$L$2:$L$90,MATCH(A3&"#1",Slots!$R$2:$R$90,0)),"") | I3: yes | J3: Mulberry Sports & Leisure Centre (Parkwood Leisure) | K3: https://pitchbooking.com/partners/MULBERRYSPORTSLEISURECENTRE | L3: Mulberry Sports & Leisure Centre reception (Parkwood Leisure) | M3: 020 7790 3854 | O3: Powerleague partner venue for leagues only: Natasha Gouveia (club manager) 0800 567 0757 partnervenues@powerleague.com | P3: =COUNTIF(Outreach!$M$3:$M$2000,A3) | Q3: =COUNTIF(Outreach!$S$3:$S$2000,A3)
A4: Shoreditch Rooftop | B4: Britannia Leisure Centre, Pitfield St, N1 5FT | C4: Available | D4: =COUNTIFS(Slots!$A$2:$A$90,A4,Slots!$I$2:$I$90,"Available") | E4: =IF(D4=0,"",_xlfn.MINIFS(Slots!$F$2:$F$90,Slots!$A$2:$A$90,A4,Slots!$I$2:$I$90,"Available")) | F4: =IFERROR(INDEX(Slots!$G$2:$G$90,MATCH(A4&"#1",Slots!$R$2:$R$90,0)),"") | G4: =IFERROR(INDEX(Slots!$J$2:$J$90,MATCH(A4&"#1",Slots!$R$2:$R$90,0)),"") | H4: =IFERROR(INDEX(Slots!$L$2:$L$90,MATCH(A4&"#1",Slots!$R$2:$R$90,0)),"") | I4: yes | J4: Better (GLL) | K4: https://bookings.better.org.uk/location/britannia-leisure-centre/3g-cage/2026-09-28/by-time | L4: Better - Britannia Leisure Centre | O4: Online at bookings.better.org.uk with a Better account. Slots released 6 days ahead. Ask Better about a block booking for later dates | P4: =COUNTIF(Outreach!$M$3:$M$2000,A4) | Q4: =COUNTIF(Outreach!$S$3:$S$2000,A4)
A5: Rosemary Gardens 3G - Islington | B5: Southgate Rd, N1 3JP | C5: No availability | D5: =COUNTIFS(Slots!$A$2:$A$90,A5,Slots!$I$2:$I$90,"Available") | E5: =IF(D5=0,"",_xlfn.MINIFS(Slots!$F$2:$F$90,Slots!$A$2:$A$90,A5,Slots!$I$2:$I$90,"Available")) | F5: =IFERROR(INDEX(Slots!$G$2:$G$90,MATCH(A5&"#1",Slots!$R$2:$R$90,0)),"") | G5: =IFERROR(INDEX(Slots!$J$2:$J$90,MATCH(A5&"#1",Slots!$R$2:$R$90,0)),"") | H5: =IFERROR(INDEX(Slots!$L$2:$L$90,MATCH(A5&"#1",Slots!$R$2:$R$90,0)),"") | I5: yes | J5: Better (GLL) - Islington | K5: https://bookings.better.org.uk/location/islington-tennis-centre/rosemary-gardens-activities | L5: Better - Islington Tennis Centre (Islington parks pitches) | O5: Online at bookings.better.org.uk with a Better account. Slots released 6 days ahead | P5: =COUNTIF(Outreach!$M$3:$M$2000,A5) | Q5: =COUNTIF(Outreach!$S$3:$S$2000,A5)
A6: Stepney 3G | B6: Globe Football Pitch, 110 Globe Rd, E1 4DZ | C6: Available | D6: =COUNTIFS(Slots!$A$2:$A$90,A6,Slots!$I$2:$I$90,"Available") | E6: =IF(D6=0,"",_xlfn.MINIFS(Slots!$F$2:$F$90,Slots!$A$2:$A$90,A6,Slots!$I$2:$I$90,"Available")) | F6: =IFERROR(INDEX(Slots!$G$2:$G$90,MATCH(A6&"#1",Slots!$R$2:$R$90,0)),"") | G6: =IFERROR(INDEX(Slots!$J$2:$J$90,MATCH(A6&"#1",Slots!$R$2:$R$90,0)),"") | H6: =IFERROR(INDEX(Slots!$L$2:$L$90,MATCH(A6&"#1",Slots!$R$2:$R$90,0)),"") | I6: unknown | J6: BookMyPitch | K6: https://bookmypitch.uk/slots/c5d1422b-8c1e-4497-b8a4-13cd96677bdc | L6: BookMyPitch (Globe Football Pitch) | O6: Venue is Globe Football Pitch 110 Globe Rd E1 4DZ. This is not the Tower Hamlets Stepney Green Park astroturf, which needs a council account. BookMyPitch venue contact for listings: masud@bookmypitch.uk | P6: =COUNTIF(Outreach!$M$3:$M$2000,A6) | Q6: =COUNTIF(Outreach!$S$3:$S$2000,A6)
A7: Old St - Moreland Primary School | B7: Gard St, EC1V 8DW | C7: Available | D7: =COUNTIFS(Slots!$A$2:$A$90,A7,Slots!$I$2:$I$90,"Available") | E7: =IF(D7=0,"",_xlfn.MINIFS(Slots!$F$2:$F$90,Slots!$A$2:$A$90,A7,Slots!$I$2:$I$90,"Available")) | F7: =IFERROR(INDEX(Slots!$G$2:$G$90,MATCH(A7&"#1",Slots!$R$2:$R$90,0)),"") | G7: =IFERROR(INDEX(Slots!$J$2:$J$90,MATCH(A7&"#1",Slots!$R$2:$R$90,0)),"") | H7: =IFERROR(INDEX(Slots!$L$2:$L$90,MATCH(A7&"#1",Slots!$R$2:$R$90,0)),"") | I7: yes | J7: PlayFootball | K7: https://www.playfootball.net/venues/old-street-moreland-school/book-a-pitch/87/6-a-side3gpitchhire | L7: PlayFootball | O7: Regular weekly bookings by enquiry via https://www.playfootball.net/contact-us (reply within 48h). One-off bookings online up to 30 days ahead | P7: =COUNTIF(Outreach!$M$3:$M$2000,A7) | Q7: =COUNTIF(Outreach!$S$3:$S$2000,A7)
A8: Hackney | B8: The City Academy Hackney, Homerton High St, E9 6JQ | C8: Available | D8: =COUNTIFS(Slots!$A$2:$A$90,A8,Slots!$I$2:$I$90,"Available") | E8: =IF(D8=0,"",_xlfn.MINIFS(Slots!$F$2:$F$90,Slots!$A$2:$A$90,A8,Slots!$I$2:$I$90,"Available")) | F8: =IFERROR(INDEX(Slots!$G$2:$G$90,MATCH(A8&"#1",Slots!$R$2:$R$90,0)),"") | G8: =IFERROR(INDEX(Slots!$J$2:$J$90,MATCH(A8&"#1",Slots!$R$2:$R$90,0)),"") | H8: =IFERROR(INDEX(Slots!$L$2:$L$90,MATCH(A8&"#1",Slots!$R$2:$R$90,0)),"") | I8: yes | J8: enni.space (The City Academy Hackney) | K8: https://enni.space/search/2872-city-academy-hackney-3g-pitch | L8: The City Academy Hackney lettings (via enni.space) | O8: Booking request on enni.space. Not instant book | P8: =COUNTIF(Outreach!$M$3:$M$2000,A8) | Q8: =COUNTIF(Outreach!$S$3:$S$2000,A8)
A9: COLA Shoreditch Park | B9: Hyde Rd, N1 5JU | C9: Available | D9: =COUNTIFS(Slots!$A$2:$A$90,A9,Slots!$I$2:$I$90,"Available") | E9: =IF(D9=0,"",_xlfn.MINIFS(Slots!$F$2:$F$90,Slots!$A$2:$A$90,A9,Slots!$I$2:$I$90,"Available")) | F9: =IFERROR(INDEX(Slots!$G$2:$G$90,MATCH(A9&"#1",Slots!$R$2:$R$90,0)),"") | G9: =IFERROR(INDEX(Slots!$J$2:$J$90,MATCH(A9&"#1",Slots!$R$2:$R$90,0)),"") | H9: =IFERROR(INDEX(Slots!$L$2:$L$90,MATCH(A9&"#1",Slots!$R$2:$R$90,0)),"") | I9: unknown | J9: enni.space (City of London Academy Shoreditch Park) | K9: https://enni.space/search/21782-cola-shoreditch-park-3g-5-a-side-pitch | L9: City of London Academy Shoreditch Park lettings (via enni.space) | O9: Pitch free 17:30-19:00. Rooftop 3G. Price-from per hour | P9: =COUNTIF(Outreach!$M$3:$M$2000,A9) | Q9: =COUNTIF(Outreach!$S$3:$S$2000,A9)
A10: Market Road | B10: Market Rd, N7 9PL | C10: Available | D10: =COUNTIFS(Slots!$A$2:$A$90,A10,Slots!$I$2:$I$90,"Available") | E10: =IF(D10=0,"",_xlfn.MINIFS(Slots!$F$2:$F$90,Slots!$A$2:$A$90,A10,Slots!$I$2:$I$90,"Available")) | F10: =IFERROR(INDEX(Slots!$G$2:$G$90,MATCH(A10&"#1",Slots!$R$2:$R$90,0)),"") | G10: =IFERROR(INDEX(Slots!$J$2:$J$90,MATCH(A10&"#1",Slots!$R$2:$R$90,0)),"") | H10: =IFERROR(INDEX(Slots!$L$2:$L$90,MATCH(A10&"#1",Slots!$R$2:$R$90,0)),"") | I10: yes | J10: Better (GLL) - Islington Tennis Centre | K10: https://bookings.better.org.uk/location/islington-tennis-centre/market-road | L10: Better - Islington Tennis Centre / PlayFootball Islington Market Road | O10: Better 5-a-side slots online 6 days ahead. PlayFootball 7-a-side pitch is online. Regular bookings by enquiry via https://www.playfootball.net/contact-us | P10: =COUNTIF(Outreach!$M$3:$M$2000,A10) | Q10: =COUNTIF(Outreach!$S$3:$S$2000,A10)

Sheet Slots
A1: Venue | B1: Date | C1: Day | D1: Start | E1: End | F1: Slot start | G1: Format | H1: Players (full pitch) | I1: Status | J1: Hire (£ per slot) | K1: Venue charges per player (£) | L1: Cost per player (£) | M1: Floodlit | N1: Booking source | O1: Booking link | P1: Notes | Q1: Rank in venue | R1: Key
A2: Haggerston Park | F2: =IF(B2="","",B2+D2) | G2: 5/7/11-a-side | H2: =IFERROR(VALUE(LEFT(G2,FIND("-",G2)-1))*2,"") | I2: Contact required | L2: =IF(J2<>"",IF(H2="","",J2/H2),IF(K2<>"",K2,"")) | M2: yes | N2: Hackney Council (GLL) | O2: https://www.hackney.gov.uk/courts-and-pitches | P2: No online calendar. Book by phone 020 8986 7955 (Mon-Fri 09:00-15:30) or hackney.marshes@gll.org. Floodlit per Playfinder listing. Playfinder also shows the venue as fully booked | Q2: =IF(I2="Available",COUNTIFS($A$2:$A$90,A2,$I$2:$I$90,"Available",$F$2:$F$90,"<"&F2)+1,"") | R2: =IF(Q2="","",A2&"#"&Q2)
A3: Whitechapel | F3: =IF(B3="","",B3+D3) | G3: 5-a-side | H3: =IFERROR(VALUE(LEFT(G3,FIND("-",G3)-1))*2,"") | I3: Contact required | L3: =IF(J3<>"",IF(H3="","",J3/H3),IF(K3<>"",K3,"")) | M3: yes | N3: Mulberry Sports & Leisure Centre (Parkwood Leisure) | O3: https://pitchbooking.com/partners/MULBERRYSPORTSLEISURECENTRE | P3: Enquiry only. Call 020 7790 3854. Centre is at Richard St E1 2JP (brief says E1 2JR). Weekday hours 18:00-22:00. Powerleague runs Mon and Tue 19:30 leagues here. Floodlit per Powerleague | Q3: =IF(I3="Available",COUNTIFS($A$2:$A$90,A3,$I$2:$I$90,"Available",$F$2:$F$90,"<"&F3)+1,"") | R3: =IF(Q3="","",A3&"#"&Q3)
